Workbook

Sheet Dashboard
A1: Control Empresa Topografia Chile
A2: Dashboard ejecutivo para gestion diaria
A4: Indicador | B4: Valor | D4: Periodo actual | E4: =MONTH(TODAY()) | F4: =YEAR(TODAY())
A5: Inversion inicial total | B5: =Configuracion!K2
A6: Monto comprado | B6: =SUMIF(Presupuesto_Inicial!I:I,"Comprado",Presupuesto_Inicial!G:G)
A7: Monto pendiente | B7: =SUMIF(Presupuesto_Inicial!I:I,"<>Comprado",Presupuesto_Inicial!G:G) | D7: Resumen mensual
A8: Facturacion mensual | B8: =SUMIFS(Ingresos!J:J,Ingresos!D:D,">="&DATE($F$4,$E$4,1),Ingresos!D:D,"<"&EDATE(DATE($F$4,$E$4,1),1)) | D8: Mes | E8: Ingresos | F8: Egresos | G8: Impuestos | H8: Saldo final
A9: Gastos mensuales | B9: =SUMIFS(Egresos!H:H,Egresos!B:B,">="&DATE($F$4,$E$4,1),Egresos!B:B,"<"&EDATE(DATE($F$4,$E$4,1),1)) | D9: 1 | E9: =SUMIFS(Flujo_Caja!D:D,Flujo_Caja!B:B,D9,Flujo_Caja!C:C,$F$4) | F9: =SUMIFS(Flujo_Caja!E:E,Flujo_Caja!B:B,D9,Flujo_Caja!C:C,$F$4) | G9: =SUMIFS(Flujo_Caja!F:F,Flujo_Caja!B:B,D9,Flujo_Caja!C:C,$F$4) | H9: =SUMIFS(Flujo_Caja!G:G,Flujo_Caja!B:B,D9,Flujo_Caja!C:C,$F$4)
A10: Impuestos estimados | B10: =SUMIFS(Impuestos!I:I,Impuestos!B:B,$E$4,Impuestos!C:C,$F$4) | D10: 2 | E10: =SUMIFS(Flujo_Caja!D:D,Flujo_Caja!B:B,D10,Flujo_Caja!C:C,$F$4) | F10: =SUMIFS(Flujo_Caja!E:E,Flujo_Caja!B:B,D10,Flujo_Caja!C:C,$F$4) | G10: =SUMIFS(Flujo_Caja!F:F,Flujo_Caja!B:B,D10,Flujo_Caja!C:C,$F$4) | H10: =SUMIFS(Flujo_Caja!G:G,Flujo_Caja!B:B,D10,Flujo_Caja!C:C,$F$4)
A11: Utilidad neta | B11: =B8-B9-B10 | D11: 3 | E11: =SUMIFS(Flujo_Caja!D:D,Flujo_Caja!B:B,D11,Flujo_Caja!C:C,$F$4) | F11: =SUMIFS(Flujo_Caja!E:E,Flujo_Caja!B:B,D11,Flujo_Caja!C:C,$F$4) | G11: =SUMIFS(Flujo_Caja!F:F,Flujo_Caja!B:B,D11,Flujo_Caja!C:C,$F$4) | H11: =SUMIFS(Flujo_Caja!G:G,Flujo_Caja!B:B,D11,Flujo_Caja!C:C,$F$4)
A12: Recuperacion inversion | B12: =IFERROR(SUM(KPI!K:K)/Configuracion!K2,0) | D12: 4 | E12: =SUMIFS(Flujo_Caja!D:D,Flujo_Caja!B:B,D12,Flujo_Caja!C:C,$F$4) | F12: =SUMIFS(Flujo_Caja!E:E,Flujo_Caja!B:B,D12,Flujo_Caja!C:C,$F$4) | G12: =SUMIFS(Flujo_Caja!F:F,Flujo_Caja!B:B,D12,Flujo_Caja!C:C,$F$4) | H12: =SUMIFS(Flujo_Caja!G:G,Flujo_Caja!B:B,D12,Flujo_Caja!C:C,$F$4)
A13: Proyectos activos | B13: =COUNTIF(Proyectos!I:I,"En ejecucion") | D13: 5 | E13: =SUMIFS(Flujo_Caja!D:D,Flujo_Caja!B:B,D13,Flujo_Caja!C:C,$F$4) | F13: =SUMIFS(Flujo_Caja!E:E,Flujo_Caja!B:B,D13,Flujo_Caja!C:C,$F$4) | G13: =SUMIFS(Flujo_Caja!F:F,Flujo_Caja!B:B,D13,Flujo_Caja!C:C,$F$4) | H13: =SUMIFS(Flujo_Caja!G:G,Flujo_Caja!B:B,D13,Flujo_Caja!C:C,$F$4)
A14: Cotizaciones pendientes | B14: =COUNTIFS(Cotizaciones!J:J,"Enviada") | D14: 6 | E14: =SUMIFS(Flujo_Caja!D:D,Flujo_Caja!B:B,D14,Flujo_Caja!C:C,$F$4) | F14: =SUMIFS(Flujo_Caja!E:E,Flujo_Caja!B:B,D14,Flujo_Caja!C:C,$F$4) | G14: =SUMIFS(Flujo_Caja!F:F,Flujo_Caja!B:B,D14,Flujo_Caja!C:C,$F$4) | H14: =SUMIFS(Flujo_Caja!G:G,Flujo_Caja!B:B,D14,Flujo_Caja!C:C,$F$4)
D15: 7 | E15: =SUMIFS(Flujo_Caja!D:D,Flujo_Caja!B:B,D15,Flujo_Caja!C:C,$F$4) | F15: =SUMIFS(Flujo_Caja!E:E,Flujo_Caja!B:B,D15,Flujo_Caja!C:C,$F$4) | G15: =SUMIFS(Flujo_Caja!F:F,Flujo_Caja!B:B,D15,Flujo_Caja!C:C,$F$4) | H15: =SUMIFS(Flujo_Caja!G:G,Flujo_Caja!B:B,D15,Flujo_Caja!C:C,$F$4)
D16: 8 | E16: =SUMIFS(Flujo_Caja!D:D,Flujo_Caja!B:B,D16,Flujo_Caja!C:C,$F$4) | F16: =SUMIFS(Flujo_Caja!E:E,Flujo_Caja!B:B,D16,Flujo_Caja!C:C,$F$4) | G16: =SUMIFS(Flujo_Caja!F:F,Flujo_Caja!B:B,D16,Flujo_Caja!C:C,$F$4) | H16: =SUMIFS(Flujo_Caja!G:G,Flujo_Caja!B:B,D16,Flujo_Caja!C:C,$F$4)
D17: 9 | E17: =SUMIFS(Flujo_Caja!D:D,Flujo_Caja!B:B,D17,Flujo_Caja!C:C,$F$4) | F17: =SUMIFS(Flujo_Caja!E:E,Flujo_Caja!B:B,D17,Flujo_Caja!C:C,$F$4) | G17: =SUMIFS(Flujo_Caja!F:F,Flujo_Caja!B:B,D17,Flujo_Caja!C:C,$F$4) | H17: =SUMIFS(Flujo_Caja!G:G,Flujo_Caja!B:B,D17,Flujo_Caja!C:C,$F$4)
D18: 10 | E18: =SUMIFS(Flujo_Caja!D:D,Flujo_Caja!B:B,D18,Flujo_Caja!C:C,$F$4) | F18: =SUMIFS(Flujo_Caja!E:E,Flujo_Caja!B:B,D18,Flujo_Caja!C:C,$F$4) | G18: =SUMIFS(Flujo_Caja!F:F,Flujo_Caja!B:B,D18,Flujo_Caja!C:C,$F$4) | H18: =SUMIFS(Flujo_Caja!G:G,Flujo_Caja!B:B,D18,Flujo_Caja!C:C,$F$4)
D19: 11 | E19: =SUMIFS(Flujo_Caja!D:D,Flujo_Caja!B:B,D19,Flujo_Caja!C:C,$F$4) | F19: =SUMIFS(Flujo_Caja!E:E,Flujo_Caja!B:B,D19,Flujo_Caja!C:C,$F$4) | G19: =SUMIFS(Flujo_Caja!F:F,Flujo_Caja!B:B,D19,Flujo_Caja!C:C,$F$4) | H19: =SUMIFS(Flujo_Caja!G:G,Flujo_Caja!B:B,D19,Flujo_Caja!C:C,$F$4)
D20: 12 | E20: =SUMIFS(Flujo_Caja!D:D,Flujo_Caja!B:B,D20,Flujo_Caja!C:C,$F$4) | F20: =SUMIFS(Flujo_Caja!E:E,Flujo_Caja!B:B,D20,Flujo_Caja!C:C,$F$4) | G20: =SUMIFS(Flujo_Caja!F:F,Flujo_Caja!B:B,D20,Flujo_Caja!C:C,$F$4) | H20: =SUMIFS(Flujo_Caja!G:G,Flujo_Caja!B:B,D20,Flujo_Caja!C:C,$F$4)

Sheet Configuracion
A1: ID_Config | B1: Nombre_Empresa | C1: RUT_Empresa | D1: Giro | E1: Fecha_Inicio | F1: Moneda | G1: IVA_Porcentaje | H1: PPM_Porcentaje | I1: Meta_Facturacion_Mensual | J1: Meta_Recuperacion_Meses | K1: Inversion_Inicial_Total | L1: Responsable | M1: Tipo_Contribuyente
A2: CFG-001 | B2: Control Empresa Topografia Chile | D2: Servicios de topografia, geomatica y apoyo tecnico | E2: 46193 | F2: CLP | G2: 0.19 | H2: 0.01 | I2: 2500000 | J2: 12 | K2: =SUM(Presupuesto_Inicial!G:G) | M2: SpA

Sheet Presupuesto_Inicial
A1: ID_Item | B1: Categoria | C1: Item | D1: Descripcion | E1: Cantidad | F1: Valor_Unitario | G1: Subtotal | H1: Prioridad | I1: Estado_Compra | J1: Fecha_Estimada_Compra | K1: Fecha_Compra_Real | L1: Proveedor | M1: Documento_Respaldo | N1: Observaciones
A2: PRE-001 | B2: Topografia | C2: GPS RTK CHCNAV i73+ o equivalente | E2: 1 | F2: 4500000 | G2: =IF(OR(E2="",F2=""),"",E2*F2) | H2: Alta | I2: Pendiente
A3: PRE-002 | B3: Topografia | C3: Tripode, baston, accesorios | E3: 1 | F3: 500000 | G3: =IF(OR(E3="",F3=""),"",E3*F3) | H3: Alta | I3: Pendiente
A4: PRE-003 | B4: Topografia | C4: Capacitacion y puesta en marcha | E4: 1 | F4: 300000 | G4: =IF(OR(E4="",F4=""),"",E4*F4) | H4: Alta | I4: Pendiente
A5: PRE-004 | B5: Computacion | C5: Notebook i7 / Ryzen 7, 32 GB RAM | E5: 1 | F5: 1300000 | G5: =IF(OR(E5="",F5=""),"",E5*F5) | H5: Alta | I5: Pendiente
A6: PRE-005 | B6: Computacion | C6: SSD externo 2 TB | E6: 1 | F6: 120000 | G6: =IF(OR(E6="",F6=""),"",E6*F6) | H6: Alta | I6: Pendiente
A7: PRE-006 | B7: Computacion | C7: Monitor 27 pulgadas | E7: 1 | F7: 180000 | G7: =IF(OR(E7="",F7=""),"",E7*F7) | H7: Alta | I7: Pendiente
A8: PRE-007 | B8: Software | C8: Licencia anual Civil 3D | E8: 1 | F8: 2500000 | G8: =IF(OR(E8="",F8=""),"",E8*F8) | H8: Alta | I8: Pendiente
A9: PRE-008 | B9: Software | C9: QGIS | E9: 1 | F9: 0 | G9: =IF(OR(E9="",F9=""),"",E9*F9) | H9: Alta | I9: Pendiente
A10: PRE-009 | B10: Software | C10: CloudCompare | E10: 1 | F10: 0 | G10: =IF(OR(E10="",F10=""),"",E10*F10) | H10: Alta | I10: Pendiente
A11: PRE-010 | B11: Software | C11: Google Earth Pro | E11: 1 | F11: 0 | G11: =IF(OR(E11="",F11=""),"",E11*F11) | H11: Alta | I11: Pendiente
A12: PRE-011 | B12: Administracion y Comercial | C12: Constitucion SpA | E12: 1 | F12: 150000 | G12: =IF(OR(E12="",F12=""),"",E12*F12) | H12: Alta | I12: Pendiente
A13: PRE-012 | B13: Administracion y Comercial | C13: Dominio web + hosting 1 año | E13: 1 | F13: 80000 | G13: =IF(OR(E13="",F13=""),"",E13*F13) | H13: Alta | I13: Pendiente
... A16: PRE-015 | B16: Administracion y Comercial | C16: Fondo contingencia / seguros | E16: 1 | F16: 500000 | G16: =IF(OR(E16="",F16=""),"",E16*F16) | H16: Alta | I16: Pendiente
G17: =IF(OR(E17="",F17=""),"",E17*F17)
G18: =IF(OR(E18="",F18=""),"",E18*F18)
G19: =IF(OR(E19="",F19=""),"",E19*F19)
G20: =IF(OR(E20="",F20=""),"",E20*F20)
G21: =IF(OR(E21="",F21=""),"",E21*F21)
G22: =IF(OR(E22="",F22=""),"",E22*F22)
G23: =IF(OR(E23="",F23=""),"",E23*F23)
G24: =IF(OR(E24="",F24=""),"",E24*F24)
G25: =IF(OR(E25="",F25=""),"",E25*F25)
G26: =IF(OR(E26="",F26=""),"",E26*F26)
G27: =IF(OR(E27="",F27=""),"",E27*F27)
G28: =IF(OR(E28="",F28=""),"",E28*F28)
... G250: =IF(OR(E250="",F250=""),"",E250*F250)

Sheet Activos
A1: ID_Activo | B1: Nombre_Activo | C1: Categoria | D1: Marca | E1: Modelo | F1: Numero_Serie | G1: Fecha_Compra | H1: Valor_Compra | I1: Vida_Util_Meses | J1: Depreciacion_Mensual | K1: Estado | L1: Ubicacion | M1: Responsable | N1: Documento_Factura | O1: Observaciones
J2: =IFERROR(H2/I2,"")
J3: =IFERROR(H3/I3,"")
J4: =IFERROR(H4/I4,"")
J5: =IFERROR(H5/I5,"")
J6: =IFERROR(H6/I6,"")
J7: =IFERROR(H7/I7,"")
J8: =IFERROR(H8/I8,"")
J9: =IFERROR(H9/I9,"")
J10: =IFERROR(H10/I10,"")
J11: =IFERROR(H11/I11,"")
J12: =IFERROR(H12/I12,"")
J13: =IFERROR(H13/I13,"")
... J250: =IFERROR(H250/I250,"")

Sheet Gastos_Mensuales
A1: ID_Gasto | B1: Mes | C1: Año | D1: Categoria | E1: Concepto | F1: Monto_Neto | G1: IVA | H1: Monto_Total | I1: Es_Recurrente | J1: Estado_Pago | K1: Fecha_Pago | L1: Documento_Respaldo | M1: Observaciones
A2: GME-001 | B2: 6 | C2: 2026 | D2: Operacion | E2: Telefonia e Internet | F2: 30000 | G2: =IF(F2="","",F2*Configuracion!$G$2) | H2: =IF(F2="","",F2+G2) | I2: TRUE | J2: Pendiente
A3: GME-002 | B3: 6 | C3: 2026 | D3: Operacion | E3: Hosting y servicios web | F3: 10000 | G3: =IF(F3="","",F3*Configuracion!$G$2) | H3: =IF(F3="","",F3+G3) | I3: TRUE | J3: Pendiente
A4: GME-003 | B4: 6 | C4: 2026 | D4: Operacion | E4: Combustible y movilizacion | F4: 200000 | G4: =IF(F4="","",F4*Configuracion!$G$2) | H4: =IF(F4="","",F4+G4) | I4: TRUE | J4: Pendiente
A5: GME-004 | B5: 6 | C5: 2026 | D5: Operacion | E5: Contabilidad | F5: 80000 | G5: =IF(F5="","",F5*Configuracion!$G$2) | H5: =IF(F5="","",F5+G5) | I5: TRUE | J5: Pendiente
A6: GME-005 | B6: 6 | C6: 2026 | D6: Operacion | E6: Imprevistos y mantencion equipos | F6: 100000 | G6: =IF(F6="","",F6*Configuracion!$G$2) | H6: =IF(F6="","",F6+G6) | I6: TRUE | J6: Pendiente
G7: =IF(F7="","",F7*Configuracion!$G$2) | H7: =IF(F7="","",F7+G7)
G8: =IF(F8="","",F8*Configuracion!$G$2) | H8: =IF(F8="","",F8+G8)
G9: =IF(F9="","",F9*Configuracion!$G$2) | H9: =IF(F9="","",F9+G9)
G10: =IF(F10="","",F10*Configuracion!$G$2) | H10: =IF(F10="","",F10+G10)
G11: =IF(F11="","",F11*Configuracion!$G$2) | H11: =IF(F11="","",F11+G11)
G12: =IF(F12="","",F12*Configuracion!$G$2) | H12: =IF(F12="","",F12+G12)
G13: =IF(F13="","",F13*Configuracion!$G$2) | H13: =IF(F13="","",F13+G13)
G14: =IF(F14="","",F14*Configuracion!$G$2) | H14: =IF(F14="","",F14+G14)
G15: =IF(F15="","",F15*Configuracion!$G$2) | H15: =IF(F15="","",F15+G15)
G16: =IF(F16="","",F16*Configuracion!$G$2) | H16: =IF(F16="","",F16+G16)
G17: =IF(F17="","",F17*Configuracion!$G$2) | H17: =IF(F17="","",F17+G17)
G18: =IF(F18="","",F18*Configuracion!$G$2) | H18: =IF(F18="","",F18+G18)
... G250: =IF(F250="","",F250*Configuracion!$G$2) | H250: =IF(F250="","",F250+G250)

Sheet Clientes
A1: ID_Cliente | B1: Nombre_Cliente | C1: Tipo_Cliente | D1: RUT | E1: Contacto | F1: Telefono | G1: Email | H1: Comuna | I1: Region | J1: Sector | K1: Estado | L1: Fuente_Contacto | M1: Fecha_Primer_Contacto | N1: Observaciones

Sheet Servicios
A1: ID_Servicio | B1: Nombre_Servicio | C1: Categoria | D1: Descripcion | E1: Precio_Minimo | F1: Precio_Maximo | G1: Unidad_Cobro | H1: Requiere_Terreno | I1: Requiere_Gabinete | J1: Documentos_Entregables | K1: Observaciones
A2: SER-001 | B2: Levantamiento topografico urbano simple | C2: Topografia | E2: 300000 | F2: 800000 | G2: Proyecto | H2: TRUE | I2: TRUE | J2: Plano, informe, archivos digitales
A3: SER-002 | B3: Levantamiento loteo/parcela | C3: Topografia | E3: 500000 | F3: 1500000 | G3: Proyecto | H3: TRUE | I3: TRUE | J3: Plano, informe, archivos digitales
A4: SER-003 | B4: Georreferenciacion de imagenes historicas | C4: GIS | E4: 200000 | F4: 800000 | G4: Proyecto | H4: TRUE | I4: TRUE | J4: Plano, informe, archivos digitales
A5: SER-004 | B5: Conversion KML/KMZ/SHP/DXF | C5: GIS | E5: 100000 | F5: 500000 | G5: Proyecto | H5: TRUE | I5: TRUE | J5: Plano, informe, archivos digitales
A6: SER-005 | B6: Cubicacion de movimiento de tierras | C6: Ingenieria | E6: 300000 | F6: 2000000 | G6: Proyecto | H6: TRUE | I6: TRUE | J6: Plano, informe, archivos digitales
A7: SER-006 | B7: Modelos digitales de terreno MDT | C7: Topografia | E7: 300000 | F7: 1500000 | G7: Proyecto | H7: TRUE | I7: TRUE | J7: Plano, informe, archivos digitales
A8: SER-007 | B8: Apoyo Oficina Tecnica | C8: Oficina Tecnica | E8: 500000 | F8: 2000000 | G8: Proyecto | H8: TRUE | I8: TRUE | J8: Plano, informe, archivos digitales
A9: SER-008 | B9: Procesamiento GIS y cartografia | C9: GIS | E9: 300000 | F9: 1500000 | G9: Proyecto | H9: TRUE | I9: TRUE | J9: Plano, informe, archivos digitales

Sheet Cotizaciones
A1: ID_Cotizacion | B1: Fecha | C1: ID_Cliente | D1: Nombre_Proyecto | E1: Servicio_Principal | F1: Descripcion | G1: Monto_Neto | H1: IVA | I1: Monto_Total | J1: Estado | K1: Fecha_Envio | L1: Fecha_Respuesta | M1: Probabilidad_Cierre | N1: Documento_Cotizacion | O1: Observaciones
H2: =IF(G2="","",G2*Configuracion!$G$2) | I2: =IF(G2="","",G2+H2)
H3: =IF(G3="","",G3*Configuracion!$G$2) | I3: =IF(G3="","",G3+H3)
H4: =IF(G4="","",G4*Configuracion!$G$2) | I4: =IF(G4="","",G4+H4)
H5: =IF(G5="","",G5*Configuracion!$G$2) | I5: =IF(G5="","",G5+H5)
H6: =IF(G6="","",G6*Configuracion!$G$2) | I6: =IF(G6="","",G6+H6)
H7: =IF(G7="","",G7*Configuracion!$G$2) | I7: =IF(G7="","",G7+H7)
H8: =IF(G8="","",G8*Configuracion!$G$2) | I8: =IF(G8="","",G8+H8)
H9: =IF(G9="","",G9*Configuracion!$G$2) | I9: =IF(G9="","",G9+H9)
H10: =IF(G10="","",G10*Configuracion!$G$2) | I10: =IF(G10="","",G10+H10)
H11: =IF(G11="","",G11*Configuracion!$G$2) | I11: =IF(G11="","",G11+H11)
H12: =IF(G12="","",G12*Configuracion!$G$2) | I12: =IF(G12="","",G12+H12)
H13: =IF(G13="","",G13*Configuracion!$G$2) | I13: =IF(G13="","",G13+H13)
... H250: =IF(G250="","",G250*Configuracion!$G$2) | I250: =IF(G250="","",G250+H250)

Sheet Proyectos
A1: ID_Proyecto | B1: ID_Cotizacion | C1: ID_Cliente | D1: Nombre_Proyecto | E1: Tipo_Servicio | F1: Fecha_Inicio | G1: Fecha_Termino_Estimada | H1: Fecha_Termino_Real | I1: Estado | J1: Monto_Contrato_Neto | K1: IVA | L1: Monto_Contrato_Total | M1: Costo_Estimado | N1: Costo_Real | O1: Utilidad_Estimada | P1: Utilidad_Real | Q1: Margen_Real_Porcentaje | R1: Ubicacion | S1: Comuna | T1: Region | U1: Responsable | V1: Observaciones
K2: =IF(J2="","",J2*Configuracion!$G$2) | L2: =IF(J2="","",J2+K2) | O2: =IF(OR(J2="",M2=""),"",J2-M2) | P2: =IF(OR(J2="",N2=""),"",J2-N2) | Q2: =IFERROR(P2/J2,"")
K3: =IF(J3="","",J3*Configuracion!$G$2) | L3: =IF(J3="","",J3+K3) | O3: =IF(OR(J3="",M3=""),"",J3-M3) | P3: =IF(OR(J3="",N3=""),"",J3-N3) | Q3: =IFERROR(P3/J3,"")
K4: =IF(J4="","",J4*Configuracion!$G$2) | L4: =IF(J4="","",J4+K4) | O4: =IF(OR(J4="",M4=""),"",J4-M4) | P4: =IF(OR(J4="",N4=""),"",J4-N4) | Q4: =IFERROR(P4/J4,"")
K5: =IF(J5="","",J5*Configuracion!$G$2) | L5: =IF(J5="","",J5+K5) | O5: =IF(OR(J5="",M5=""),"",J5-M5) | P5: =IF(OR(J5="",N5=""),"",J5-N5) | Q5: =IFERROR(P5/J5,"")
K6: =IF(J6="","",J6*Configuracion!$G$2) | L6: =IF(J6="","",J6+K6) | O6: =IF(OR(J6="",M6=""),"",J6-M6) | P6: =IF(OR(J6="",N6=""),"",J6-N6) | Q6: =IFERROR(P6/J6,"")
K7: =IF(J7="","",J7*Configuracion!$G$2) | L7: =IF(J7="","",J7+K7) | O7: =IF(OR(J7="",M7=""),"",J7-M7) | P7: =IF(OR(J7="",N7=""),"",J7-N7) | Q7: =IFERROR(P7/J7,"")
K8: =IF(J8="","",J8*Configuracion!$G$2) | L8: =IF(J8="","",J8+K8) | O8: =IF(OR(J8="",M8=""),"",J8-M8) | P8: =IF(OR(J8="",N8=""),"",J8-N8) | Q8: =IFERROR(P8/J8,"")
K9: =IF(J9="","",J9*Configuracion!$G$2) | L9: =IF(J9="","",J9+K9) | O9: =IF(OR(J9="",M9=""),"",J9-M9) | P9: =IF(OR(J9="",N9=""),"",J9-N9) | Q9: =IFERROR(P9/J9,"")
K10: =IF(J10="","",J10*Configuracion!$G$2) | L10: =IF(J10="","",J10+K10) | O10: =IF(OR(J10="",M10=""),"",J10-M10) | P10: =IF(OR(J10="",N10=""),"",J10-N10) | Q10: =IFERROR(P10/J10,"")
K11: =IF(J11="","",J11*Configuracion!$G$2) | L11: =IF(J11="","",J11+K11) | O11: =IF(OR(J11="",M11=""),"",J11-M11) | P11: =IF(OR(J11="",N11=""),"",J11-N11) | Q11: =IFERROR(P11/J11,"")
K12: =IF(J12="","",J12*Configuracion!$G$2) | L12: =IF(J12="","",J12+K12) | O12: =IF(OR(J12="",M12=""),"",J12-M12) | P12: =IF(OR(J12="",N12=""),"",J12-N12) | Q12: =IFERROR(P12/J12,"")
K13: =IF(J13="","",J13*Configuracion!$G$2) | L13: =IF(J13="","",J13+K13) | O13: =IF(OR(J13="",M13=""),"",J13-M13) | P13: =IF(OR(J13="",N13=""),"",J13-N13) | Q13: =IFERROR(P13/J13,"")
... K250: =IF(J250="","",J250*Configuracion!$G$2) | L250: =IF(J250="","",J250+K250) | O250: =IF(OR(J250="",M250=""),"",J250-M250) | P250: =IF(OR(J250="",N250=""),"",J250-N250) | Q250: =IFERROR(P250/J250,"")

Sheet Ingresos
A1: ID_Ingreso | B1: ID_Proyecto | C1: ID_Cliente | D1: Fecha_Emision | E1: Fecha_Pago | F1: Tipo_Documento | G1: Numero_Documento | H1: Monto_Neto | I1: IVA | J1: Monto_Total | K1: Retencion | L1: PPM | M1: Monto_Liquido | N1: Estado_Cobro | O1: Documento_Respaldo | P1: Observaciones
I2: =IF(H2="","",H2*Configuracion!$G$2) | J2: =IF(H2="","",H2+I2) | L2: =IF(H2="","",H2*Configuracion!$H$2) | M2: =IF(H2="","",J2-K2-L2)
I3: =IF(H3="","",H3*Configuracion!$G$2) | J3: =IF(H3="","",H3+I3) | L3: =IF(H3="","",H3*Configuracion!$H$2) | M3: =IF(H3="","",J3-K3-L3)
I4: =IF(H4="","",H4*Configuracion!$G$2) | J4: =IF(H4="","",H4+I4) | L4: =IF(H4="","",H4*Configuracion!$H$2) | M4: =IF(H4="","",J4-K4-L4)
I5: =IF(H5="","",H5*Configuracion!$G$2) | J5: =IF(H5="","",H5+I5) | L5: =IF(H5="","",H5*Configuracion!$H$2) | M5: =IF(H5="","",J5-K5-L5)
I6: =IF(H6="","",H6*Configuracion!$G$2) | J6: =IF(H6="","",H6+I6) | L6: =IF(H6="","",H6*Configuracion!$H$2) | M6: =IF(H6="","",J6-K6-L6)
I7: =IF(H7="","",H7*Configuracion!$G$2) | J7: =IF(H7="","",H7+I7) | L7: =IF(H7="","",H7*Configuracion!$H$2) | M7: =IF(H7="","",J7-K7-L7)
I8: =IF(H8="","",H8*Configuracion!$G$2) | J8: =IF(H8="","",H8+I8) | L8: =IF(H8="","",H8*Configuracion!$H$2) | M8: =IF(H8="","",J8-K8-L8)
I9: =IF(H9="","",H9*Configuracion!$G$2) | J9: =IF(H9="","",H9+I9) | L9: =IF(H9="","",H9*Configuracion!$H$2) | M9: =IF(H9="","",J9-K9-L9)
I10: =IF(H10="","",H10*Configuracion!$G$2) | J10: =IF(H10="","",H10+I10) | L10: =IF(H10="","",H10*Configuracion!$H$2) | M10: =IF(H10="","",J10-K10-L10)
I11: =IF(H11="","",H11*Configuracion!$G$2) | J11: =IF(H11="","",H11+I11) | L11: =IF(H11="","",H11*Configuracion!$H$2) | M11: =IF(H11="","",J11-K11-L11)
I12: =IF(H12="","",H12*Configuracion!$G$2) | J12: =IF(H12="","",H12+I12) | L12: =IF(H12="","",H12*Configuracion!$H$2) | M12: =IF(H12="","",J12-K12-L12)
I13: =IF(H13="","",H13*Configuracion!$G$2) | J13: =IF(H13="","",H13+I13) | L13: =IF(H13="","",H13*Configuracion!$H$2) | M13: =IF(H13="","",J13-K13-L13)
... I250: =IF(H250="","",H250*Configuracion!$G$2) | J250: =IF(H250="","",H250+I250) | L250: =IF(H250="","",H250*Configuracion!$H$2) | M250: =IF(H250="","",J250-K250-L250)

Sheet Egresos
A1: ID_Egreso | B1: Fecha | C1: Categoria | D1: Concepto | E1: Proveedor | F1: Monto_Neto | G1: IVA | H1: Monto_Total | I1: Medio_Pago | J1: Estado_Pago | K1: Documento_Respaldo | L1: Es_Deducible | M1: Observaciones
G2: =IF(F2="","",F2*Configuracion!$G$2) | H2: =IF(F2="","",F2+G2)
G3: =IF(F3="","",F3*Configuracion!$G$2) | H3: =IF(F3="","",F3+G3)
G4: =IF(F4="","",F4*Configuracion!$G$2) | H4: =IF(F4="","",F4+G4)
G5: =IF(F5="","",F5*Configuracion!$G$2) | H5: =IF(F5="","",F5+G5)
G6: =IF(F6="","",F6*Configuracion!$G$2) | H6: =IF(F6="","",F6+G6)
G7: =IF(F7="","",F7*Configuracion!$G$2) | H7: =IF(F7="","",F7+G7)
G8: =IF(F8="","",F8*Configuracion!$G$2) | H8: =IF(F8="","",F8+G8)
G9: =IF(F9="","",F9*Configuracion!$G$2) | H9: =IF(F9="","",F9+G9)
G10: =IF(F10="","",F10*Configuracion!$G$2) | H10: =IF(F10="","",F10+G10)
G11: =IF(F11="","",F11*Configuracion!$G$2) | H11: =IF(F11="","",F11+G11)
G12: =IF(F12="","",F12*Configuracion!$G$2) | H12: =IF(F12="","",F12+G12)
G13: =IF(F13="","",F13*Configuracion!$G$2) | H13: =IF(F13="","",F13+G13)
... G250: =IF(F250="","",F250*Configuracion!$G$2) | H250: =IF(F250="","",F250+G250)

Sheet Impuestos
A1: ID_Impuesto | B1: Mes | C1: Año | D1: IVA_Debito | E1: IVA_Credito | F1: IVA_A_Pagar | G1: PPM | H1: Otros_Impuestos | I1: Total_Impuestos | J1: Estado | K1: Fecha_Pago | L1: Documento_Respaldo | M1: Observaciones
A2: IMP-01-2026 | B2: 1 | C2: 2026 | D2: =SUMIFS(Ingresos!I:I,Ingresos!D:D,">="&DATE(C2,B2,1),Ingresos!D:D,"<"&EDATE(DATE(C2,B2,1),1)) | E2: =SUMIFS(Egresos!G:G,Egresos!B:B,">="&DATE(C2,B2,1),Egresos!B:B,"<"&EDATE(DATE(C2,B2,1),1),Egresos!L:L,TRUE) | F2: =MAX(D2-E2,0) | G2: =SUMIFS(Ingresos!L:L,Ingresos!D:D,">="&DATE(C2,B2,1),Ingresos!D:D,"<"&EDATE(DATE(C2,B2,1),1)) | H2: 0 | I2: =F2+G2+H2 | J2: Pendiente
A3: IMP-02-2026 | B3: 2 | C3: 2026 | D3: =SUMIFS(Ingresos!I:I,Ingresos!D:D,">="&DATE(C3,B3,1),Ingresos!D:D,"<"&EDATE(DATE(C3,B3,1),1)) | E3: =SUMIFS(Egresos!G:G,Egresos!B:B,">="&DATE(C3,B3,1),Egresos!B:B,"<"&EDATE(DATE(C3,B3,1),1),Egresos!L:L,TRUE) | F3: =MAX(D3-E3,0) | G3: =SUMIFS(Ingresos!L:L,Ingresos!D:D,">="&DATE(C3,B3,1),Ingresos!D:D,"<"&EDATE(DATE(C3,B3,1),1)) | H3: 0 | I3: =F3+G3+H3 | J3: Pendiente
A4: IMP-03-2026 | B4: 3 | C4: 2026 | D4: =SUMIFS(Ingresos!I:I,Ingresos!D:D,">="&DATE(C4,B4,1),Ingresos!D:D,"<"&EDATE(DATE(C4,B4,1),1)) | E4: =SUMIFS(Egresos!G:G,Egresos!B:B,">="&DATE(C4,B4,1),Egresos!B:B,"<"&EDATE(DATE(C4,B4,1),1),Egresos!L:L,TRUE) | F4: =MAX(D4-E4,0) | G4: =SUMIFS(Ingresos!L:L,Ingresos!D:D,">="&DATE(C4,B4,1),Ingresos!D:D,"<"&EDATE(DATE(C4,B4,1),1)) | H4: 0 | I4: =F4+G4+H4 | J4: Pendiente
A5: IMP-04-2026 | B5: 4 | C5: 2026 | D5: =SUMIFS(Ingresos!I:I,Ingresos!D:D,">="&DATE(C5,B5,1),Ingresos!D:D,"<"&EDATE(DATE(C5,B5,1),1)) | E5: =SUMIFS(Egresos!G:G,Egresos!B:B,">="&DATE(C5,B5,1),Egresos!B:B,"<"&EDATE(DATE(C5,B5,1),1),Egresos!L:L,TRUE) | F5: =MAX(D5-E5,0) | G5: =SUMIFS(Ingresos!L:L,Ingresos!D:D,">="&DATE(C5,B5,1),Ingresos!D:D,"<"&EDATE(DATE(C5,B5,1),1)) | H5: 0 | I5: =F5+G5+H5 | J5: Pendiente
A6: IMP-05-2026 | B6: 5 | C6: 2026 | D6: =SUMIFS(Ingresos!I:I,Ingresos!D:D,">="&DATE(C6,B6,1),Ingresos!D:D,"<"&EDATE(DATE(C6,B6,1),1)) | E6: =SUMIFS(Egresos!G:G,Egresos!B:B,">="&DATE(C6,B6,1),Egresos!B:B,"<"&EDATE(DATE(C6,B6,1),1),Egresos!L:L,TRUE) | F6: =MAX(D6-E6,0) | G6: =SUMIFS(Ingresos!L:L,Ingresos!D:D,">="&DATE(C6,B6,1),Ingresos!D:D,"<"&EDATE(DATE(C6,B6,1),1)) | H6: 0 | I6: =F6+G6+H6 | J6: Pendiente
A7: IMP-06-2026 | B7: 6 | C7: 2026 | D7: =SUMIFS(Ingresos!I:I,Ingresos!D:D,">="&DATE(C7,B7,1),Ingresos!D:D,"<"&EDATE(DATE(C7,B7,1),1)) | E7: =SUMIFS(Egresos!G:G,Egresos!B:B,">="&DATE(C7,B7,1),Egresos!B:B,"<"&EDATE(DATE(C7,B7,1),1),Egresos!L:L,TRUE) | F7: =MAX(D7-E7,0) | G7: =SUMIFS(Ingresos!L:L,Ingresos!D:D,">="&DATE(C7,B7,1),Ingresos!D:D,"<"&EDATE(DATE(C7,B7,1),1)) | H7: 0 | I7: =F7+G7+H7 | J7: Pendiente
A8: IMP-07-2026 | B8: 7 | C8: 2026 | D8: =SUMIFS(Ingresos!I:I,Ingresos!D:D,">="&DATE(C8,B8,1),Ingresos!D:D,"<"&EDATE(DATE(C8,B8,1),1)) | E8: =SUMIFS(Egresos!G:G,Egresos!B:B,">="&DATE(C8,B8,1),Egresos!B:B,"<"&EDATE(DATE(C8,B8,1),1),Egresos!L:L,TRUE) | F8: =MAX(D8-E8,0) | G8: =SUMIFS(Ingresos!L:L,Ingresos!D:D,">="&DATE(C8,B8,1),Ingresos!D:D,"<"&EDATE(DATE(C8,B8,1),1)) | H8: 0 | I8: =F8+G8+H8 | J8: Pendiente
A9: IMP-08-2026 | B9: 8 | C9: 2026 | D9: =SUMIFS(Ingresos!I:I,Ingresos!D:D,">="&DATE(C9,B9,1),Ingresos!D:D,"<"&EDATE(DATE(C9,B9,1),1)) | E9: =SUMIFS(Egresos!G:G,Egresos!B:B,">="&DATE(C9,B9,1),Egresos!B:B,"<"&EDATE(DATE(C9,B9,1),1),Egresos!L:L,TRUE) | F9: =MAX(D9-E9,0) | G9: =SUMIFS(Ingresos!L:L,Ingresos!D:D,">="&DATE(C9,B9,1),Ingresos!D:D,"<"&EDATE(DATE(C9,B9,1),1)) | H9: 0 | I9: =F9+G9+H9 | J9: Pendiente
A10: IMP-09-2026 | B10: 9 | C10: 2026 | D10: =SUMIFS(Ingresos!I:I,Ingresos!D:D,">="&DATE(C10,B10,1),Ingresos!D:D,"<"&EDATE(DATE(C10,B10,1),1)) | E10: =SUMIFS(Egresos!G:G,Egresos!B:B,">="&DATE(C10,B10,1),Egresos!B:B,"<"&EDATE(DATE(C10,B10,1),1),Egresos!L:L,TRUE) | F10: =MAX(D10-E10,0) | G10: =SUMIFS(Ingresos!L:L,Ingresos!D:D,">="&DATE(C10,B10,1),Ingresos!D:D,"<"&EDATE(DATE(C10,B10,1),1)) | H10: 0 | I10: =F10+G10+H10 | J10: Pendiente
A11: IMP-10-2026 | B11: 10 | C11: 2026 | D11: =SUMIFS(Ingresos!I:I,Ingresos!D:D,">="&DATE(C11,B11,1),Ingresos!D:D,"<"&EDATE(DATE(C11,B11,1),1)) | E11: =SUMIFS(Egresos!G:G,Egresos!B:B,">="&DATE(C11,B11,1),Egresos!B:B,"<"&EDATE(DATE(C11,B11,1),1),Egresos!L:L,TRUE) | F11: =MAX(D11-E11,0) | G11: =SUMIFS(Ingresos!L:L,Ingresos!D:D,">="&DATE(C11,B11,1),Ingresos!D:D,"<"&EDATE(DATE(C11,B11,1),1)) | H11: 0 | I11: =F11+G11+H11 | J11: Pendiente
A12: IMP-11-2026 | B12: 11 | C12: 2026 | D12: =SUMIFS(Ingresos!I:I,Ingresos!D:D,">="&DATE(C12,B12,1),Ingresos!D:D,"<"&EDATE(DATE(C12,B12,1),1)) | E12: =SUMIFS(Egresos!G:G,Egresos!B:B,">="&DATE(C12,B12,1),Egresos!B:B,"<"&EDATE(DATE(C12,B12,1),1),Egresos!L:L,TRUE) | F12: =MAX(D12-E12,0) | G12: =SUMIFS(Ingresos!L:L,Ingresos!D:D,">="&DATE(C12,B12,1),Ingresos!D:D,"<"&EDATE(DATE(C12,B12,1),1)) | H12: 0 | I12: =F12+G12+H12 | J12: Pendiente
A13: IMP-12-2026 | B13: 12 | C13: 2026 | D13: =SUMIFS(Ingresos!I:I,Ingresos!D:D,">="&DATE(C13,B13,1),Ingresos!D:D,"<"&EDATE(DATE(C13,B13,1),1)) | E13: =SUMIFS(Egresos!G:G,Egresos!B:B,">="&DATE(C13,B13,1),Egresos!B:B,"<"&EDATE(DATE(C13,B13,1),1),Egresos!L:L,TRUE) | F13: =MAX(D13-E13,0) | G13: =SUMIFS(Ingresos!L:L,Ingresos!D:D,">="&DATE(C13,B13,1),Ingresos!D:D,"<"&EDATE(DATE(C13,B13,1),1)) | H13: 0 | I13: =F13+G13+H13 | J13: Pendiente
D14: =SUMIFS(Ingresos!I:I,Ingresos!D:D,">="&DATE(C14,B14,1),Ingresos!D:D,"<"&EDATE(DATE(C14,B14,1),1)) | E14: =SUMIFS(Egresos!G:G,Egresos!B:B,">="&DATE(C14,B14,1),Egresos!B:B,"<"&EDATE(DATE(C14,B14,1),1),Egresos!L:L,TRUE) | F14: =MAX(D14-E14,0) | G14: =SUMIFS(Ingresos!L:L,Ingresos!D:D,">="&DATE(C14,B14,1),Ingresos!D:D,"<"&EDATE(DATE(C14,B14,1),1)) | I14: =F14+G14+H14
D15: =SUMIFS(Ingresos!I:I,Ingresos!D:D,">="&DATE(C15,B15,1),Ingresos!D:D,"<"&EDATE(DATE(C15,B15,1),1)) | E15: =SUMIFS(Egresos!G:G,Egresos!B:B,">="&DATE(C15,B15,1),Egresos!B:B,"<"&EDATE(DATE(C15,B15,1),1),Egresos!L:L,TRUE) | F15: =MAX(D15-E15,0) | G15: =SUMIFS(Ingresos!L:L,Ingresos!D:D,">="&DATE(C15,B15,1),Ingresos!D:D,"<"&EDATE(DATE(C15,B15,1),1)) | I15: =F15+G15+H15
D16: =SUMIFS(Ingresos!I:I,Ingresos!D:D,">="&DATE(C16,B16,1),Ingresos!D:D,"<"&EDATE(DATE(C16,B16,1),1)) | E16: =SUMIFS(Egresos!G:G,Egresos!B:B,">="&DATE(C16,B16,1),Egresos!B:B,"<"&EDATE(DATE(C16,B16,1),1),Egresos!L:L,TRUE) | F16: =MAX(D16-E16,0) | G16: =SUMIFS(Ingresos!L:L,Ingresos!D:D,">="&DATE(C16,B16,1),Ingresos!D:D,"<"&EDATE(DATE(C16,B16,1),1)) | I16: =F16+G16+H16
D17: =SUMIFS(Ingresos!I:I,Ingresos!D:D,">="&DATE(C17,B17,1),Ingresos!D:D,"<"&EDATE(DATE(C17,B17,1),1)) | E17: =SUMIFS(Egresos!G:G,Egresos!B:B,">="&DATE(C17,B17,1),Egresos!B:B,"<"&EDATE(DATE(C17,B17,1),1),Egresos!L:L,TRUE) | F17: =MAX(D17-E17,0) | G17: =SUMIFS(Ingresos!L:L,Ingresos!D:D,">="&DATE(C17,B17,1),Ingresos!D:D,"<"&EDATE(DATE(C17,B17,1),1)) | I17: =F17+G17+H17
D18: =SUMIFS(Ingresos!I:I,Ingresos!D:D,">="&DATE(C18,B18,1),Ingresos!D:D,"<"&EDATE(DATE(C18,B18,1),1)) | E18: =SUMIFS(Egresos!G:G,Egresos!B:B,">="&DATE(C18,B18,1),Egresos!B:B,"<"&EDATE(DATE(C18,B18,1),1),Egresos!L:L,TRUE) | F18: =MAX(D18-E18,0) | G18: =SUMIFS(Ingresos!L:L,Ingresos!D:D,">="&DATE(C18,B18,1),Ingresos!D:D,"<"&EDATE(DATE(C18,B18,1),1)) | I18: =F18+G18+H18
D19: =SUMIFS(Ingresos!I:I,Ingresos!D:D,">="&DATE(C19,B19,1),Ingresos!D:D,"<"&EDATE(DATE(C19,B19,1),1)) | E19: =SUMIFS(Egresos!G:G,Egresos!B:B,">="&DATE(C19,B19,1),Egresos!B:B,"<"&EDATE(DATE(C19,B19,1),1),Egresos!L:L,TRUE) | F19: =MAX(D19-E19,0) | G19: =SUMIFS(Ingresos!L:L,Ingresos!D:D,">="&DATE(C19,B19,1),Ingresos!D:D,"<"&EDATE(DATE(C19,B19,1),1)) | I19: =F19+G19+H19
D20: =SUMIFS(Ingresos!I:I,Ingresos!D:D,">="&DATE(C20,B20,1),Ingresos!D:D,"<"&EDATE(DATE(C20,B20,1),1)) | E20: =SUMIFS(Egresos!G:G,Egresos!B:B,">="&DATE(C20,B20,1),Egresos!B:B,"<"&EDATE(DATE(C20,B20,1),1),Egresos!L:L,TRUE) | F20: =MAX(D20-E20,0) | G20: =SUMIFS(Ingresos!L:L,Ingresos!D:D,">="&DATE(C20,B20,1),Ingresos!D:D,"<"&EDATE(DATE(C20,B20,1),1)) | I20: =F20+G20+H20
D21: =SUMIFS(Ingresos!I:I,Ingresos!D:D,">="&DATE(C21,B21,1),Ingresos!D:D,"<"&EDATE(DATE(C21,B21,1),1)) | E21: =SUMIFS(Egresos!G:G,Egresos!B:B,">="&DATE(C21,B21,1),Egresos!B:B,"<"&EDATE(DATE(C21,B21,1),1),Egresos!L:L,TRUE) | F21: =MAX(D21-E21,0) | G21: =SUMIFS(Ingresos!L:L,Ingresos!D:D,">="&DATE(C21,B21,1),Ingresos!D:D,"<"&EDATE(DATE(C21,B21,1),1)) | I21: =F21+G21+H21
D22: =SUMIFS(Ingresos!I:I,Ingresos!D:D,">="&DATE(C22,B22,1),Ingresos!D:D,"<"&EDATE(DATE(C22,B22,1),1)) | E22: =SUMIFS(Egresos!G:G,Egresos!B:B,">="&DATE(C22,B22,1),Egresos!B:B,"<"&EDATE(DATE(C22,B22,1),1),Egresos!L:L,TRUE) | F22: =MAX(D22-E22,0) | G22: =SUMIFS(Ingresos!L:L,Ingresos!D:D,">="&DATE(C22,B22,1),Ingresos!D:D,"<"&EDATE(DATE(C22,B22,1),1)) | I22: =F22+G22+H22
D23: =SUMIFS(Ingresos!I:I,Ingresos!D:D,">="&DATE(C23,B23,1),Ingresos!D:D,"<"&EDATE(DATE(C23,B23,1),1)) | E23: =SUMIFS(Egresos!G:G,Egresos!B:B,">="&DATE(C23,B23,1),Egresos!B:B,"<"&EDATE(DATE(C23,B23,1),1),Egresos!L:L,TRUE) | F23: =MAX(D23-E23,0) | G23: =SUMIFS(Ingresos!L:L,Ingresos!D:D,">="&DATE(C23,B23,1),Ingresos!D:D,"<"&EDATE(DATE(C23,B23,1),1)) | I23: =F23+G23+H23
D24: =SUMIFS(Ingresos!I:I,Ingresos!D:D,">="&DATE(C24,B24,1),Ingresos!D:D,"<"&EDATE(DATE(C24,B24,1),1)) | E24: =SUMIFS(Egresos!G:G,Egresos!B:B,">="&DATE(C24,B24,1),Egresos!B:B,"<"&EDATE(DATE(C24,B24,1),1),Egresos!L:L,TRUE) | F24: =MAX(D24-E24,0) | G24: =SUMIFS(Ingresos!L:L,Ingresos!D:D,">="&DATE(C24,B24,1),Ingresos!D:D,"<"&EDATE(DATE(C24,B24,1),1)) | I24: =F24+G24+H24
D25: =SUMIFS(Ingresos!I:I,Ingresos!D:D,">="&DATE(C25,B25,1),Ingresos!D:D,"<"&EDATE(DATE(C25,B25,1),1)) | E25: =SUMIFS(Egresos!G:G,Egresos!B:B,">="&DATE(C25,B25,1),Egresos!B:B,"<"&EDATE(DATE(C25,B25,1),1),Egresos!L:L,TRUE) | F25: =MAX(D25-E25,0) | G25: =SUMIFS(Ingresos!L:L,Ingresos!D:D,">="&DATE(C25,B25,1),Ingresos!D:D,"<"&EDATE(DATE(C25,B25,1),1)) | I25: =F25+G25+H25
... D250: =SUMIFS(Ingresos!I:I,Ingresos!D:D,">="&DATE(C250,B250,1),Ingresos!D:D,"<"&EDATE(DATE(C250,B250,1),1)) | E250: =SUMIFS(Egresos!G:G,Egresos!B:B,">="&DATE(C250,B250,1),Egresos!B:B,"<"&EDATE(DATE(C250,B250,1),1),Egresos!L:L,TRUE) | F250: =MAX(D250-E250,0) | G250: =SUMIFS(Ingresos!L:L,Ingresos!D:D,">="&DATE(C250,B250,1),Ingresos!D:D,"<"&EDATE(DATE(C250,B250,1),1)) | I250: =F250+G250+H250

Sheet Flujo_Caja
A1: ID_Flujo | B1: Mes | C1: Año | D1: Saldo_Inicial | E1: Total_Ingresos | F1: Total_Egresos | G1: Total_Impuestos | H1: Saldo_Final | I1: Observaciones
A2: FLU-01-2026 | B2: 1 | C2: 2026 | D2: 0 | E2: =SUMIFS(Ingresos!J:J,Ingresos!D:D,">="&DATE(C2,B2,1),Ingresos!D:D,"<"&EDATE(DATE(C2,B2,1),1)) | F2: =SUMIFS(Egresos!H:H,Egresos!B:B,">="&DATE(C2,B2,1),Egresos!B:B,"<"&EDATE(DATE(C2,B2,1),1))+SUMIFS(Gastos_Mensuales!H:H,Gastos_Mensuales!B:B,B2,Gastos_Mensuales!C:C,C2) | G2: =SUMIFS(Impuestos!I:I,Impuestos!B:B,B2,Impuestos!C:C,C2) | H2: =D2+E2-F2-G2
A3: FLU-02-2026 | B3: 2 | C3: 2026 | D3: 0 | E3: =SUMIFS(Ingresos!J:J,Ingresos!D:D,">="&DATE(C3,B3,1),Ingresos!D:D,"<"&EDATE(DATE(C3,B3,1),1)) | F3: =SUMIFS(Egresos!H:H,Egresos!B:B,">="&DATE(C3,B3,1),Egresos!B:B,"<"&EDATE(DATE(C3,B3,1),1))+SUMIFS(Gastos_Mensuales!H:H,Gastos_Mensuales!B:B,B3,Gastos_Mensuales!C:C,C3) | G3: =SUMIFS(Impuestos!I:I,Impuestos!B:B,B3,Impuestos!C:C,C3) | H3: =D3+E3-F3-G3
A4: FLU-03-2026 | B4: 3 | C4: 2026 | D4: 0 | E4: =SUMIFS(Ingresos!J:J,Ingresos!D:D,">="&DATE(C4,B4,1),Ingresos!D:D,"<"&EDATE(DATE(C4,B4,1),1)) | F4: =SUMIFS(Egresos!H:H,Egresos!B:B,">="&DATE(C4,B4,1),Egresos!B:B,"<"&EDATE(DATE(C4,B4,1),1))+SUMIFS(Gastos_Mensuales!H:H,Gastos_Mensuales!B:B,B4,Gastos_Mensuales!C:C,C4) | G4: =SUMIFS(Impuestos!I:I,Impuestos!B:B,B4,Impuestos!C:C,C4) | H4: =D4+E4-F4-G4
A5: FLU-04-2026 | B5: 4 | C5: 2026 | D5: 0 | E5: =SUMIFS(Ingresos!J:J,Ingresos!D:D,">="&DATE(C5,B5,1),Ingresos!D:D,"<"&EDATE(DATE(C5,B5,1),1)) | F5: =SUMIFS(Egresos!H:H,Egresos!B:B,">="&DATE(C5,B5,1),Egresos!B:B,"<"&EDATE(DATE(C5,B5,1),1))+SUMIFS(Gastos_Mensuales!H:H,Gastos_Mensuales!B:B,B5,Gastos_Mensuales!C:C,C5) | G5: =SUMIFS(Impuestos!I:I,Impuestos!B:B,B5,Impuestos!C:C,C5) | H5: =D5+E5-F5-G5
A6: FLU-05-2026 | B6: 5 | C6: 2026 | D6: 0 | E6: =SUMIFS(Ingresos!J:J,Ingresos!D:D,">="&DATE(C6,B6,1),Ingresos!D:D,"<"&EDATE(DATE(C6,B6,1),1)) | F6: =SUMIFS(Egresos!H:H,Egresos!B:B,">="&DATE(C6,B6,1),Egresos!B:B,"<"&EDATE(DATE(C6,B6,1),1))+SUMIFS(Gastos_Mensuales!H:H,Gastos_Mensuales!B:B,B6,Gastos_Mensuales!C:C,C6) | G6: =SUMIFS(Impuestos!I:I,Impuestos!B:B,B6,Impuestos!C:C,C6) | H6: =D6+E6-F6-G6
A7: FLU-06-2026 | B7: 6 | C7: 2026 | D7: 0 | E7: =SUMIFS(Ingresos!J:J,Ingresos!D:D,">="&DATE(C7,B7,1),Ingresos!D:D,"<"&EDATE(DATE(C7,B7,1),1)) | F7: =SUMIFS(Egresos!H:H,Egresos!B:B,">="&DATE(C7,B7,1),Egresos!B:B,"<"&EDATE(DATE(C7,B7,1),1))+SUMIFS(Gastos_Mensuales!H:H,Gastos_Mensuales!B:B,B7,Gastos_Mensuales!C:C,C7) | G7: =SUMIFS(Impuestos!I:I,Impuestos!B:B,B7,Impuestos!C:C,C7) | H7: =D7+E7-F7-G7
A8: FLU-07-2026 | B8: 7 | C8: 2026 | D8: 0 | E8: =SUMIFS(Ingresos!J:J,Ingresos!D:D,">="&DATE(C8,B8,1),Ingresos!D:D,"<"&EDATE(DATE(C8,B8,1),1)) | F8: =SUMIFS(Egresos!H:H,Egresos!B:B,">="&DATE(C8,B8,1),Egresos!B:B,"<"&EDATE(DATE(C8,B8,1),1))+SUMIFS(Gastos_Mensuales!H:H,Gastos_Mensuales!B:B,B8,Gastos_Mensuales!C:C,C8) | G8: =SUMIFS(Impuestos!I:I,Impuestos!B:B,B8,Impuestos!C:C,C8) | H8: =D8+E8-F8-G8
A9: FLU-08-2026 | B9: 8 | C9: 2026 | D9: 0 | E9: =SUMIFS(Ingresos!J:J,Ingresos!D:D,">="&DATE(C9,B9,1),Ingresos!D:D,"<"&EDATE(DATE(C9,B9,1),1)) | F9: =SUMIFS(Egresos!H:H,Egresos!B:B,">="&DATE(C9,B9,1),Egresos!B:B,"<"&EDATE(DATE(C9,B9,1),1))+SUMIFS(Gastos_Mensuales!H:H,Gastos_Mensuales!B:B,B9,Gastos_Mensuales!C:C,C9) | G9: =SUMIFS(Impuestos!I:I,Impuestos!B:B,B9,Impuestos!C:C,C9) | H9: =D9+E9-F9-G9
A10: FLU-09-2026 | B10: 9 | C10: 2026 | D10: 0 | E10: =SUMIFS(Ingresos!J:J,Ingresos!D:D,">="&DATE(C10,B10,1),Ingresos!D:D,"<"&EDATE(DATE(C10,B10,1),1)) | F10: =SUMIFS(Egresos!H:H,Egresos!B:B,">="&DATE(C10,B10,1),Egresos!B:B,"<"&EDATE(DATE(C10,B10,1),1))+SUMIFS(Gastos_Mensuales!H:H,Gastos_Mensuales!B:B,B10,Gastos_Mensuales!C:C,C10) | G10: =SUMIFS(Impuestos!I:I,Impuestos!B:B,B10,Impuestos!C:C,C10) | H10: =D10+E10-F10-G10
A11: FLU-10-2026 | B11: 10 | C11: 2026 | D11: 0 | E11: =SUMIFS(Ingresos!J:J,Ingresos!D:D,">="&DATE(C11,B11,1),Ingresos!D:D,"<"&EDATE(DATE(C11,B11,1),1)) | F11: =SUMIFS(Egresos!H:H,Egresos!B:B,">="&DATE(C11,B11,1),Egresos!B:B,"<"&EDATE(DATE(C11,B11,1),1))+SUMIFS(Gastos_Mensuales!H:H,Gastos_Mensuales!B:B,B11,Gastos_Mensuales!C:C,C11) | G11: =SUMIFS(Impuestos!I:I,Impuestos!B:B,B11,Impuestos!C:C,C11) | H11: =D11+E11-F11-G11
A12: FLU-11-2026 | B12: 11 | C12: 2026 | D12: 0 | E12: =SUMIFS(Ingresos!J:J,Ingresos!D:D,">="&DATE(C12,B12,1),Ingresos!D:D,"<"&EDATE(DATE(C12,B12,1),1)) | F12: =SUMIFS(Egresos!H:H,Egresos!B:B,">="&DATE(C12,B12,1),Egresos!B:B,"<"&EDATE(DATE(C12,B12,1),1))+SUMIFS(Gastos_Mensuales!H:H,Gastos_Mensuales!B:B,B12,Gastos_Mensuales!C:C,C12) | G12: =SUMIFS(Impuestos!I:I,Impuestos!B:B,B12,Impuestos!C:C,C12) | H12: =D12+E12-F12-G12
A13: FLU-12-2026 | B13: 12 | C13: 2026 | D13: 0 | E13: =SUMIFS(Ingresos!J:J,Ingresos!D:D,">="&DATE(C13,B13,1),Ingresos!D:D,"<"&EDATE(DATE(C13,B13,1),1)) | F13: =SUMIFS(Egresos!H:H,Egresos!B:B,">="&DATE(C13,B13,1),Egresos!B:B,"<"&EDATE(DATE(C13,B13,1),1))+SUMIFS(Gastos_Mensuales!H:H,Gastos_Mensuales!B:B,B13,Gastos_Mensuales!C:C,C13) | G13: =SUMIFS(Impuestos!I:I,Impuestos!B:B,B13,Impuestos!C:C,C13) | H13: =D13+E13-F13-G13
E14: =SUMIFS(Ingresos!J:J,Ingresos!D:D,">="&DATE(C14,B14,1),Ingresos!D:D,"<"&EDATE(DATE(C14,B14,1),1)) | F14: =SUMIFS(Egresos!H:H,Egresos!B:B,">="&DATE(C14,B14,1),Egresos!B:B,"<"&EDATE(DATE(C14,B14,1),1))+SUMIFS(Gastos_Mensuales!H:H,Gastos_Mensuales!B:B,B14,Gastos_Mensuales!C:C,C14) | G14: =SUMIFS(Impuestos!I:I,Impuestos!B:B,B14,Impuestos!C:C,C14) | H14: =D14+E14-F14-G14
E15: =SUMIFS(Ingresos!J:J,Ingresos!D:D,">="&DATE(C15,B15,1),Ingresos!D:D,"<"&EDATE(DATE(C15,B15,1),1)) | F15: =SUMIFS(Egresos!H:H,Egresos!B:B,">="&DATE(C15,B15,1),Egresos!B:B,"<"&EDATE(DATE(C15,B15,1),1))+SUMIFS(Gastos_Mensuales!H:H,Gastos_Mensuales!B:B,B15,Gastos_Mensuales!C:C,C15) | G15: =SUMIFS(Impuestos!I:I,Impuestos!B:B,B15,Impuestos!C:C,C15) | H15: =D15+E15-F15-G15
E16: =SUMIFS(Ingresos!J:J,Ingresos!D:D,">="&DATE(C16,B16,1),Ingresos!D:D,"<"&EDATE(DATE(C16,B16,1),1)) | F16: =SUMIFS(Egresos!H:H,Egresos!B:B,">="&DATE(C16,B16,1),Egresos!B:B,"<"&EDATE(DATE(C16,B16,1),1))+SUMIFS(Gastos_Mensuales!H:H,Gastos_Mensuales!B:B,B16,Gastos_Mensuales!C:C,C16) | G16: =SUMIFS(Impuestos!I:I,Impuestos!B:B,B16,Impuestos!C:C,C16) | H16: =D16+E16-F16-G16
E17: =SUMIFS(Ingresos!J:J,Ingresos!D:D,">="&DATE(C17,B17,1),Ingresos!D:D,"<"&EDATE(DATE(C17,B17,1),1)) | F17: =SUMIFS(Egresos!H:H,Egresos!B:B,">="&DATE(C17,B17,1),Egresos!B:B,"<"&EDATE(DATE(C17,B17,1),1))+SUMIFS(Gastos_Mensuales!H:H,Gastos_Mensuales!B:B,B17,Gastos_Mensuales!C:C,C17) | G17: =SUMIFS(Impuestos!I:I,Impuestos!B:B,B17,Impuestos!C:C,C17) | H17: =D17+E17-F17-G17
E18: =SUMIFS(Ingresos!J:J,Ingresos!D:D,">="&DATE(C18,B18,1),Ingresos!D:D,"<"&EDATE(DATE(C18,B18,1),1)) | F18: =SUMIFS(Egresos!H:H,Egresos!B:B,">="&DATE(C18,B18,1),Egresos!B:B,"<"&EDATE(DATE(C18,B18,1),1))+SUMIFS(Gastos_Mensuales!H:H,Gastos_Mensuales!B:B,B18,Gastos_Mensuales!C:C,C18) | G18: =SUMIFS(Impuestos!I:I,Impuestos!B:B,B18,Impuestos!C:C,C18) | H18: =D18+E18-F18-G18
E19: =SUMIFS(Ingresos!J:J,Ingresos!D:D,">="&DATE(C19,B19,1),Ingresos!D:D,"<"&EDATE(DATE(C19,B19,1),1)) | F19: =SUMIFS(Egresos!H:H,Egresos!B:B,">="&DATE(C19,B19,1),Egresos!B:B,"<"&EDATE(DATE(C19,B19,1),1))+SUMIFS(Gastos_Mensuales!H:H,Gastos_Mensuales!B:B,B19,Gastos_Mensuales!C:C,C19) | G19: =SUMIFS(Impuestos!I:I,Impuestos!B:B,B19,Impuestos!C:C,C19) | H19: =D19+E19-F19-G19
E20: =SUMIFS(Ingresos!J:J,Ingresos!D:D,">="&DATE(C20,B20,1),Ingresos!D:D,"<"&EDATE(DATE(C20,B20,1),1)) | F20: =SUMIFS(Egresos!H:H,Egresos!B:B,">="&DATE(C20,B20,1),Egresos!B:B,"<"&EDATE(DATE(C20,B20,1),1))+SUMIFS(Gastos_Mensuales!H:H,Gastos_Mensuales!B:B,B20,Gastos_Mensuales!C:C,C20) | G20: =SUMIFS(Impuestos!I:I,Impuestos!B:B,B20,Impuestos!C:C,C20) | H20: =D20+E20-F20-G20
E21: =SUMIFS(Ingresos!J:J,Ingresos!D:D,">="&DATE(C21,B21,1),Ingresos!D:D,"<"&EDATE(DATE(C21,B21,1),1)) | F21: =SUMIFS(Egresos!H:H,Egresos!B:B,">="&DATE(C21,B21,1),Egresos!B:B,"<"&EDATE(DATE(C21,B21,1),1))+SUMIFS(Gastos_Mensuales!H:H,Gastos_Mensuales!B:B,B21,Gastos_Mensuales!C:C,C21) | G21: =SUMIFS(Impuestos!I:I,Impuestos!B:B,B21,Impuestos!C:C,C21) | H21: =D21+E21-F21-G21
E22: =SUMIFS(Ingresos!J:J,Ingresos!D:D,">="&DATE(C22,B22,1),Ingresos!D:D,"<"&EDATE(DATE(C22,B22,1),1)) | F22: =SUMIFS(Egresos!H:H,Egresos!B:B,">="&DATE(C22,B22,1),Egresos!B:B,"<"&EDATE(DATE(C22,B22,1),1))+SUMIFS(Gastos_Mensuales!H:H,Gastos_Mensuales!B:B,B22,Gastos_Mensuales!C:C,C22) | G22: =SUMIFS(Impuestos!I:I,Impuestos!B:B,B22,Impuestos!C:C,C22) | H22: =D22+E22-F22-G22
E23: =SUMIFS(Ingresos!J:J,Ingresos!D:D,">="&DATE(C23,B23,1),Ingresos!D:D,"<"&EDATE(DATE(C23,B23,1),1)) | F23: =SUMIFS(Egresos!H:H,Egresos!B:B,">="&DATE(C23,B23,1),Egresos!B:B,"<"&EDATE(DATE(C23,B23,1),1))+SUMIFS(Gastos_Mensuales!H:H,Gastos_Mensuales!B:B,B23,Gastos_Mensuales!C:C,C23) | G23: =SUMIFS(Impuestos!I:I,Impuestos!B:B,B23,Impuestos!C:C,C23) | H23: =D23+E23-F23-G23
E24: =SUMIFS(Ingresos!J:J,Ingresos!D:D,">="&DATE(C24,B24,1),Ingresos!D:D,"<"&EDATE(DATE(C24,B24,1),1)) | F24: =SUMIFS(Egresos!H:H,Egresos!B:B,">="&DATE(C24,B24,1),Egresos!B:B,"<"&EDATE(DATE(C24,B24,1),1))+SUMIFS(Gastos_Mensuales!H:H,Gastos_Mensuales!B:B,B24,Gastos_Mensuales!C:C,C24) | G24: =SUMIFS(Impuestos!I:I,Impuestos!B:B,B24,Impuestos!C:C,C24) | H24: =D24+E24-F24-G24
E25: =SUMIFS(Ingresos!J:J,Ingresos!D:D,">="&DATE(C25,B25,1),Ingresos!D:D,"<"&EDATE(DATE(C25,B25,1),1)) | F25: =SUMIFS(Egresos!H:H,Egresos!B:B,">="&DATE(C25,B25,1),Egresos!B:B,"<"&EDATE(DATE(C25,B25,1),1))+SUMIFS(Gastos_Mensuales!H:H,Gastos_Mensuales!B:B,B25,Gastos_Mensuales!C:C,C25) | G25: =SUMIFS(Impuestos!I:I,Impuestos!B:B,B25,Impuestos!C:C,C25) | H25: =D25+E25-F25-G25
... E250: =SUMIFS(Ingresos!J:J,Ingresos!D:D,">="&DATE(C250,B250,1),Ingresos!D:D,"<"&EDATE(DATE(C250,B250,1),1)) | F250: =SUMIFS(Egresos!H:H,Egresos!B:B,">="&DATE(C250,B250,1),Egresos!B:B,"<"&EDATE(DATE(C250,B250,1),1))+SUMIFS(Gastos_Mensuales!H:H,Gastos_Mensuales!B:B,B250,Gastos_Mensuales!C:C,C250) | G250: =SUMIFS(Impuestos!I:I,Impuestos!B:B,B250,Impuestos!C:C,C250) | H250: =D250+E250-F250-G250

Sheet Roadmap
A1: ID_Tarea | B1: Etapa | C1: Tarea | D1: Descripcion | E1: Prioridad | F1: Responsable | G1: Fecha_Inicio | H1: Fecha_Limite | I1: Fecha_Cierre | J1: Estado | K1: Porcentaje_Avance | L1: Dependencia | M1: Documento_Asociado | N1: Observaciones
A2: TAR-001 | B2: Formalizacion | C2: Definir tipo de contribuyente y nombre comercial | E2: Alta | J2: Pendiente | K2: 0
A3: TAR-002 | B3: Compra de equipos | C3: Cotizar GPS RTK y accesorios | E3: Alta | J3: Pendiente | K3: 0
A4: TAR-003 | B4: Imagen comercial | C4: Crear dominio, correo y pagina web basica | E4: Alta | J4: Pendiente | K4: 0
A5: TAR-004 | B5: Captacion de clientes | C5: Armar base inicial de prospectos | E5: Alta | J5: Pendiente | K5: 0
A6: TAR-005 | B6: Primeros proyectos | C6: Levantar primeras cotizaciones pagadas | E6: Media | J6: Pendiente | K6: 0
A7: TAR-006 | B7: Control financiero | C7: Registrar ingresos, egresos e impuestos mensuales | E7: Media | J7: Pendiente | K7: 0
A8: TAR-007 | B8: Regularizacion tributaria | C8: Validar flujo mensual con contador | E8: Media | J8: Pendiente | K8: 0
A9: TAR-008 | B9: Consolidacion urbana | C9: Estandarizar plantillas de entrega tecnica | E9: Media | J9: Pendiente | K9: 0
A10: TAR-009 | B10: Entrada a mineria | C10: Diseñar modulo futuro de faenas, HSE y produccion | E10: Media | J10: Pendiente | K10: 0
A11: TAR-010 | B11: Evolucion consultora | C11: Definir cartera de ingenieria, GIS, QA/QC y BIM | E11: Media | J11: Pendiente | K11: 0

Sheet Documentos
A1: ID_Documento | B1: Categoria | C1: Nombre_Documento | D1: Fecha | E1: Relacionado_A | F1: ID_Relacionado | G1: Archivo | H1: Vencimiento | I1: Estado | J1: Observaciones

Sheet KPI
A1: ID_KPI | B1: Mes | C1: Año | D1: Facturacion_Total | E1: Gastos_Totales | F1: Utilidad_Neta | G1: Margen_Neto | H1: Cotizaciones_Enviadas | I1: Cotizaciones_Aprobadas | J1: Tasa_Conversion | K1: Inversion_Recuperada | L1: Porcentaje_Recuperacion_Inversion | M1: Saldo_Caja | N1: Observaciones
A2: KPI-01-2026 | B2: 1 | C2: 2026 | D2: =SUMIFS(Ingresos!J:J,Ingresos!D:D,">="&DATE(C2,B2,1),Ingresos!D:D,"<"&EDATE(DATE(C2,B2,1),1)) | E2: =SUMIFS(Egresos!H:H,Egresos!B:B,">="&DATE(C2,B2,1),Egresos!B:B,"<"&EDATE(DATE(C2,B2,1),1))+SUMIFS(Gastos_Mensuales!H:H,Gastos_Mensuales!B:B,B2,Gastos_Mensuales!C:C,C2)+SUMIFS(Impuestos!I:I,Impuestos!B:B,B2,Impuestos!C:C,C2) | F2: =D2-E2 | G2: =IFERROR(F2/D2,0) | H2: =COUNTIFS(Cotizaciones!J:J,"Enviada",Cotizaciones!B:B,">="&DATE(C2,B2,1),Cotizaciones!B:B,"<"&EDATE(DATE(C2,B2,1),1)) | I2: =COUNTIFS(Cotizaciones!J:J,"Aprobada",Cotizaciones!B:B,">="&DATE(C2,B2,1),Cotizaciones!B:B,"<"&EDATE(DATE(C2,B2,1),1)) | J2: =IFERROR(I2/H2,0) | K2: =MAX(0,SUM($F$2:F2)) | L2: =IFERROR(K2/Configuracion!$K$2,0) | M2: =SUMIFS(Flujo_Caja!H:H,Flujo_Caja!B:B,B2,Flujo_Caja!C:C,C2)
A3: KPI-02-2026 | B3: 2 | C3: 2026 | D3: =SUMIFS(Ingresos!J:J,Ingresos!D:D,">="&DATE(C3,B3,1),Ingresos!D:D,"<"&EDATE(DATE(C3,B3,1),1)) | E3: =SUMIFS(Egresos!H:H,Egresos!B:B,">="&DATE(C3,B3,1),Egresos!B:B,"<"&EDATE(DATE(C3,B3,1),1))+SUMIFS(Gastos_Mensuales!H:H,Gastos_Mensuales!B:B,B3,Gastos_Mensuales!C:C,C3)+SUMIFS(Impuestos!I:I,Impuestos!B:B,B3,Impuestos!C:C,C3) | F3: =D3-E3 | G3: =IFERROR(F3/D3,0) | H3: =COUNTIFS(Cotizaciones!J:J,"Enviada",Cotizaciones!B:B,">="&DATE(C3,B3,1),Cotizaciones!B:B,"<"&EDATE(DATE(C3,B3,1),1)) | I3: =COUNTIFS(Cotizaciones!J:J,"Aprobada",Cotizaciones!B:B,">="&DATE(C3,B3,1),Cotizaciones!B:B,"<"&EDATE(DATE(C3,B3,1),1)) | J3: =IFERROR(I3/H3,0) | K3: =MAX(0,SUM($F$2:F3)) | L3: =IFERROR(K3/Configuracion!$K$2,0) | M3: =SUMIFS(Flujo_Caja!H:H,Flujo_Caja!B:B,B3,Flujo_Caja!C:C,C3)
A4: KPI-03-2026 | B4: 3 | C4: 2026 | D4: =SUMIFS(Ingresos!J:J,Ingresos!D:D,">="&DATE(C4,B4,1),Ingresos!D:D,"<"&EDATE(DATE(C4,B4,1),1)) | E4: =SUMIFS(Egresos!H:H,Egresos!B:B,">="&DATE(C4,B4,1),Egresos!B:B,"<"&EDATE(DATE(C4,B4,1),1))+SUMIFS(Gastos_Mensuales!H:H,Gastos_Mensuales!B:B,B4,Gastos_Mensuales!C:C,C4)+SUMIFS(Impuestos!I:I,Impuestos!B:B,B4,Impuestos!C:C,C4) | F4: =D4-E4 | G4: =IFERROR(F4/D4,0) | H4: =COUNTIFS(Cotizaciones!J:J,"Enviada",Cotizaciones!B:B,">="&DATE(C4,B4,1),Cotizaciones!B:B,"<"&EDATE(DATE(C4,B4,1),1)) | I4: =COUNTIFS(Cotizaciones!J:J,"Aprobada",Cotizaciones!B:B,">="&DATE(C4,B4,1),Cotizaciones!B:B,"<"&EDATE(DATE(C4,B4,1),1)) | J4: =IFERROR(I4/H4,0) | K4: =MAX(0,SUM($F$2:F4)) | L4: =IFERROR(K4/Configuracion!$K$2,0) | M4: =SUMIFS(Flujo_Caja!H:H,Flujo_Caja!B:B,B4,Flujo_Caja!C:C,C4)
A5: KPI-04-2026 | B5: 4 | C5: 2026 | D5: =SUMIFS(Ingresos!J:J,Ingresos!D:D,">="&DATE(C5,B5,1),Ingresos!D:D,"<"&EDATE(DATE(C5,B5,1),1)) | E5: =SUMIFS(Egresos!H:H,Egresos!B:B,">="&DATE(C5,B5,1),Egresos!B:B,"<"&EDATE(DATE(C5,B5,1),1))+SUMIFS(Gastos_Mensuales!H:H,Gastos_Mensuales!B:B,B5,Gastos_Mensuales!C:C,C5)+SUMIFS(Impuestos!I:I,Impuestos!B:B,B5,Impuestos!C:C,C5) | F5: =D5-E5 | G5: =IFERROR(F5/D5,0) | H5: =COUNTIFS(Cotizaciones!J:J,"Enviada",Cotizaciones!B:B,">="&DATE(C5,B5,1),Cotizaciones!B:B,"<"&EDATE(DATE(C5,B5,1),1)) | I5: =COUNTIFS(Cotizaciones!J:J,"Aprobada",Cotizaciones!B:B,">="&DATE(C5,B5,1),Cotizaciones!B:B,"<"&EDATE(DATE(C5,B5,1),1)) | J5: =IFERROR(I5/H5,0) | K5: =MAX(0,SUM($F$2:F5)) | L5: =IFERROR(K5/Configuracion!$K$2,0) | M5: =SUMIFS(Flujo_Caja!H:H,Flujo_Caja!B:B,B5,Flujo_Caja!C:C,C5)
A6: KPI-05-2026 | B6: 5 | C6: 2026 | D6: =SUMIFS(Ingresos!J:J,Ingresos!D:D,">="&DATE(C6,B6,1),Ingresos!D:D,"<"&EDATE(DATE(C6,B6,1),1)) | E6: =SUMIFS(Egresos!H:H,Egresos!B:B,">="&DATE(C6,B6,1),Egresos!B:B,"<"&EDATE(DATE(C6,B6,1),1))+SUMIFS(Gastos_Mensuales!H:H,Gastos_Mensuales!B:B,B6,Gastos_Mensuales!C:C,C6)+SUMIFS(Impuestos!I:I,Impuestos!B:B,B6,Impuestos!C:C,C6) | F6: =D6-E6 | G6: =IFERROR(F6/D6,0) | H6: =COUNTIFS(Cotizaciones!J:J,"Enviada",Cotizaciones!B:B,">="&DATE(C6,B6,1),Cotizaciones!B:B,"<"&EDATE(DATE(C6,B6,1),1)) | I6: =COUNTIFS(Cotizaciones!J:J,"Aprobada",Cotizaciones!B:B,">="&DATE(C6,B6,1),Cotizaciones!B:B,"<"&EDATE(DATE(C6,B6,1),1)) | J6: =IFERROR(I6/H6,0) | K6: =MAX(0,SUM($F$2:F6)) | L6: =IFERROR(K6/Configuracion!$K$2,0) | M6: =SUMIFS(Flujo_Caja!H:H,Flujo_Caja!B:B,B6,Flujo_Caja!C:C,C6)
A7: KPI-06-2026 | B7: 6 | C7: 2026 | D7: =SUMIFS(Ingresos!J:J,Ingresos!D:D,">="&DATE(C7,B7,1),Ingresos!D:D,"<"&EDATE(DATE(C7,B7,1),1)) | E7: =SUMIFS(Egresos!H:H,Egresos!B:B,">="&DATE(C7,B7,1),Egresos!B:B,"<"&EDATE(DATE(C7,B7,1),1))+SUMIFS(Gastos_Mensuales!H:H,Gastos_Mensuales!B:B,B7,Gastos_Mensuales!C:C,C7)+SUMIFS(Impuestos!I:I,Impuestos!B:B,B7,Impuestos!C:C,C7) | F7: =D7-E7 | G7: =IFERROR(F7/D7,0) | H7: =COUNTIFS(Cotizaciones!J:J,"Enviada",Cotizaciones!B:B,">="&DATE(C7,B7,1),Cotizaciones!B:B,"<"&EDATE(DATE(C7,B7,1),1)) | I7: =COUNTIFS(Cotizaciones!J:J,"Aprobada",Cotizaciones!B:B,">="&DATE(C7,B7,1),Cotizaciones!B:B,"<"&EDATE(DATE(C7,B7,1),1)) | J7: =IFERROR(I7/H7,0) | K7: =MAX(0,SUM($F$2:F7)) | L7: =IFERROR(K7/Configuracion!$K$2,0) | M7: =SUMIFS(Flujo_Caja!H:H,Flujo_Caja!B:B,B7,Flujo_Caja!C:C,C7)
A8: KPI-07-2026 | B8: 7 | C8: 2026 | D8: =SUMIFS(Ingresos!J:J,Ingresos!D:D,">="&DATE(C8,B8,1),Ingresos!D:D,"<"&EDATE(DATE(C8,B8,1),1)) | E8: =SUMIFS(Egresos!H:H,Egresos!B:B,">="&DATE(C8,B8,1),Egresos!B:B,"<"&EDATE(DATE(C8,B8,1),1))+SUMIFS(Gastos_Mensuales!H:H,Gastos_Mensuales!B:B,B8,Gastos_Mensuales!C:C,C8)+SUMIFS(Impuestos!I:I,Impuestos!B:B,B8,Impuestos!C:C,C8) | F8: =D8-E8 | G8: =IFERROR(F8/D8,0) | H8: =COUNTIFS(Cotizaciones!J:J,"Enviada",Cotizaciones!B:B,">="&DATE(C8,B8,1),Cotizaciones!B:B,"<"&EDATE(DATE(C8,B8,1),1)) | I8: =COUNTIFS(Cotizaciones!J:J,"Aprobada",Cotizaciones!B:B,">="&DATE(C8,B8,1),Cotizaciones!B:B,"<"&EDATE(DATE(C8,B8,1),1)) | J8: =IFERROR(I8/H8,0) | K8: =MAX(0,SUM($F$2:F8)) | L8: =IFERROR(K8/Configuracion!$K$2,0) | M8: =SUMIFS(Flujo_Caja!H:H,Flujo_Caja!B:B,B8,Flujo_Caja!C:C,C8)
A9: KPI-08-2026 | B9: 8 | C9: 2026 | D9: =SUMIFS(Ingresos!J:J,Ingresos!D:D,">="&DATE(C9,B9,1),Ingresos!D:D,"<"&EDATE(DATE(C9,B9,1),1)) | E9: =SUMIFS(Egresos!H:H,Egresos!B:B,">="&DATE(C9,B9,1),Egresos!B:B,"<"&EDATE(DATE(C9,B9,1),1))+SUMIFS(Gastos_Mensuales!H:H,Gastos_Mensuales!B:B,B9,Gastos_Mensuales!C:C,C9)+SUMIFS(Impuestos!I:I,Impuestos!B:B,B9,Impuestos!C:C,C9) | F9: =D9-E9 | G9: =IFERROR(F9/D9,0) | H9: =COUNTIFS(Cotizaciones!J:J,"Enviada",Cotizaciones!B:B,">="&DATE(C9,B9,1),Cotizaciones!B:B,"<"&EDATE(DATE(C9,B9,1),1)) | I9: =COUNTIFS(Cotizaciones!J:J,"Aprobada",Cotizaciones!B:B,">="&DATE(C9,B9,1),Cotizaciones!B:B,"<"&EDATE(DATE(C9,B9,1),1)) | J9: =IFERROR(I9/H9,0) | K9: =MAX(0,SUM($F$2:F9)) | L9: =IFERROR(K9/Configuracion!$K$2,0) | M9: =SUMIFS(Flujo_Caja!H:H,Flujo_Caja!B:B,B9,Flujo_Caja!C:C,C9)
A10: KPI-09-2026 | B10: 9 | C10: 2026 | D10: =SUMIFS(Ingresos!J:J,Ingresos!D:D,">="&DATE(C10,B10,1),Ingresos!D:D,"<"&EDATE(DATE(C10,B10,1),1)) | E10: =SUMIFS(Egresos!H:H,Egresos!B:B,">="&DATE(C10,B10,1),Egresos!B:B,"<"&EDATE(DATE(C10,B10,1),1))+SUMIFS(Gastos_Mensuales!H:H,Gastos_Mensuales!B:B,B10,Gastos_Mensuales!C:C,C10)+SUMIFS(Impuestos!I:I,Impuestos!B:B,B10,Impuestos!C:C,C10) | F10: =D10-E10 | G10: =IFERROR(F10/D10,0) | H10: =COUNTIFS(Cotizaciones!J:J,"Enviada",Cotizaciones!B:B,">="&DATE(C10,B10,1),Cotizaciones!B:B,"<"&EDATE(DATE(C10,B10,1),1)) | I10: =COUNTIFS(Cotizaciones!J:J,"Aprobada",Cotizaciones!B:B,">="&DATE(C10,B10,1),Cotizaciones!B:B,"<"&EDATE(DATE(C10,B10,1),1)) | J10: =IFERROR(I10/H10,0) | K10: =MAX(0,SUM($F$2:F10)) | L10: =IFERROR(K10/Configuracion!$K$2,0) | M10: =SUMIFS(Flujo_Caja!H:H,Flujo_Caja!B:B,B10,Flujo_Caja!C:C,C10)
A11: KPI-10-2026 | B11: 10 | C11: 2026 | D11: =SUMIFS(Ingresos!J:J,Ingresos!D:D,">="&DATE(C11,B11,1),Ingresos!D:D,"<"&EDATE(DATE(C11,B11,1),1)) | E11: =SUMIFS(Egresos!H:H,Egresos!B:B,">="&DATE(C11,B11,1),Egresos!B:B,"<"&EDATE(DATE(C11,B11,1),1))+SUMIFS(Gastos_Mensuales!H:H,Gastos_Mensuales!B:B,B11,Gastos_Mensuales!C:C,C11)+SUMIFS(Impuestos!I:I,Impuestos!B:B,B11,Impuestos!C:C,C11) | F11: =D11-E11 | G11: =IFERROR(F11/D11,0) | H11: =COUNTIFS(Cotizaciones!J:J,"Enviada",Cotizaciones!B:B,">="&DATE(C11,B11,1),Cotizaciones!B:B,"<"&EDATE(DATE(C11,B11,1),1)) | I11: =COUNTIFS(Cotizaciones!J:J,"Aprobada",Cotizaciones!B:B,">="&DATE(C11,B11,1),Cotizaciones!B:B,"<"&EDATE(DATE(C11,B11,1),1)) | J11: =IFERROR(I11/H11,0) | K11: =MAX(0,SUM($F$2:F11)) | L11: =IFERROR(K11/Configuracion!$K$2,0) | M11: =SUMIFS(Flujo_Caja!H:H,Flujo_Caja!B:B,B11,Flujo_Caja!C:C,C11)
A12: KPI-11-2026 | B12: 11 | C12: 2026 | D12: =SUMIFS(Ingresos!J:J,Ingresos!D:D,">="&DATE(C12,B12,1),Ingresos!D:D,"<"&EDATE(DATE(C12,B12,1),1)) | E12: =SUMIFS(Egresos!H:H,Egresos!B:B,">="&DATE(C12,B12,1),Egresos!B:B,"<"&EDATE(DATE(C12,B12,1),1))+SUMIFS(Gastos_Mensuales!H:H,Gastos_Mensuales!B:B,B12,Gastos_Mensuales!C:C,C12)+SUMIFS(Impuestos!I:I,Impuestos!B:B,B12,Impuestos!C:C,C12) | F12: =D12-E12 | G12: =IFERROR(F12/D12,0) | H12: =COUNTIFS(Cotizaciones!J:J,"Enviada",Cotizaciones!B:B,">="&DATE(C12,B12,1),Cotizaciones!B:B,"<"&EDATE(DATE(C12,B12,1),1)) | I12: =COUNTIFS(Cotizaciones!J:J,"Aprobada",Cotizaciones!B:B,">="&DATE(C12,B12,1),Cotizaciones!B:B,"<"&EDATE(DATE(C12,B12,1),1)) | J12: =IFERROR(I12/H12,0) | K12: =MAX(0,SUM($F$2:F12)) | L12: =IFERROR(K12/Configuracion!$K$2,0) | M12: =SUMIFS(Flujo_Caja!H:H,Flujo_Caja!B:B,B12,Flujo_Caja!C:C,C12)
A13: KPI-12-2026 | B13: 12 | C13: 2026 | D13: =SUMIFS(Ingresos!J:J,Ingresos!D:D,">="&DATE(C13,B13,1),Ingresos!D:D,"<"&EDATE(DATE(C13,B13,1),1)) | E13: =SUMIFS(Egresos!H:H,Egresos!B:B,">="&DATE(C13,B13,1),Egresos!B:B,"<"&EDATE(DATE(C13,B13,1),1))+SUMIFS(Gastos_Mensuales!H:H,Gastos_Mensuales!B:B,B13,Gastos_Mensuales!C:C,C13)+SUMIFS(Impuestos!I:I,Impuestos!B:B,B13,Impuestos!C:C,C13) | F13: =D13-E13 | G13: =IFERROR(F13/D13,0) | H13: =COUNTIFS(Cotizaciones!J:J,"Enviada",Cotizaciones!B:B,">="&DATE(C13,B13,1),Cotizaciones!B:B,"<"&EDATE(DATE(C13,B13,1),1)) | I13: =COUNTIFS(Cotizaciones!J:J,"Aprobada",Cotizaciones!B:B,">="&DATE(C13,B13,1),Cotizaciones!B:B,"<"&EDATE(DATE(C13,B13,1),1)) | J13: =IFERROR(I13/H13,0) | K13: =MAX(0,SUM($F$2:F13)) | L13: =IFERROR(K13/Configuracion!$K$2,0) | M13: =SUMIFS(Flujo_Caja!H:H,Flujo_Caja!B:B,B13,Flujo_Caja!C:C,C13)
D14: =SUMIFS(Ingresos!J:J,Ingresos!D:D,">="&DATE(C14,B14,1),Ingresos!D:D,"<"&EDATE(DATE(C14,B14,1),1)) | E14: =SUMIFS(Egresos!H:H,Egresos!B:B,">="&DATE(C14,B14,1),Egresos!B:B,"<"&EDATE(DATE(C14,B14,1),1))+SUMIFS(Gastos_Mensuales!H:H,Gastos_Mensuales!B:B,B14,Gastos_Mensuales!C:C,C14)+SUMIFS(Impuestos!I:I,Impuestos!B:B,B14,Impuestos!C:C,C14) | F14: =D14-E14 | G14: =IFERROR(F14/D14,0) | H14: =COUNTIFS(Cotizaciones!J:J,"Enviada",Cotizaciones!B:B,">="&DATE(C14,B14,1),Cotizaciones!B:B,"<"&EDATE(DATE(C14,B14,1),1)) | I14: =COUNTIFS(Cotizaciones!J:J,"Aprobada",Cotizaciones!B:B,">="&DATE(C14,B14,1),Cotizaciones!B:B,"<"&EDATE(DATE(C14,B14,1),1)) | J14: =IFERROR(I14/H14,0) | K14: =MAX(0,SUM($F$2:F14)) | L14: =IFERROR(K14/Configuracion!$K$2,0) | M14: =SUMIFS(Flujo_Caja!H:H,Flujo_Caja!B:B,B14,Flujo_Caja!C:C,C14)
D15: =SUMIFS(Ingresos!J:J,Ingresos!D:D,">="&DATE(C15,B15,1),Ingresos!D:D,"<"&EDATE(DATE(C15,B15,1),1)) | E15: =SUMIFS(Egresos!H:H,Egresos!B:B,">="&DATE(C15,B15,1),Egresos!B:B,"<"&EDATE(DATE(C15,B15,1),1))+SUMIFS(Gastos_Mensuales!H:H,Gastos_Mensuales!B:B,B15,Gastos_Mensuales!C:C,C15)+SUMIFS(Impuestos!I:I,Impuestos!B:B,B15,Impuestos!C:C,C15) | F15: =D15-E15 | G15: =IFERROR(F15/D15,0) | H15: =COUNTIFS(Cotizaciones!J:J,"Enviada",Cotizaciones!B:B,">="&DATE(C15,B15,1),Cotizaciones!B:B,"<"&EDATE(DATE(C15,B15,1),1)) | I15: =COUNTIFS(Cotizaciones!J:J,"Aprobada",Cotizaciones!B:B,">="&DATE(C15,B15,1),Cotizaciones!B:B,"<"&EDATE(DATE(C15,B15,1),1)) | J15: =IFERROR(I15/H15,0) | K15: =MAX(0,SUM($F$2:F15)) | L15: =IFERROR(K15/Configuracion!$K$2,0) | M15: =SUMIFS(Flujo_Caja!H:H,Flujo_Caja!B:B,B15,Flujo_Caja!C:C,C15)
D16: =SUMIFS(Ingresos!J:J,Ingresos!D:D,">="&DATE(C16,B16,1),Ingresos!D:D,"<"&EDATE(DATE(C16,B16,1),1)) | E16: =SUMIFS(Egresos!H:H,Egresos!B:B,">="&DATE(C16,B16,1),Egresos!B:B,"<"&EDATE(DATE(C16,B16,1),1))+SUMIFS(Gastos_Mensuales!H:H,Gastos_Mensuales!B:B,B16,Gastos_Mensuales!C:C,C16)+SUMIFS(Impuestos!I:I,Impuestos!B:B,B16,Impuestos!C:C,C16) | F16: =D16-E16 | G16: =IFERROR(F16/D16,0) | H16: =COUNTIFS(Cotizaciones!J:J,"Enviada",Cotizaciones!B:B,">="&DATE(C16,B16,1),Cotizaciones!B:B,"<"&EDATE(DATE(C16,B16,1),1)) | I16: =COUNTIFS(Cotizaciones!J:J,"Aprobada",Cotizaciones!B:B,">="&DATE(C16,B16,1),Cotizaciones!B:B,"<"&EDATE(DATE(C16,B16,1),1)) | J16: =IFERROR(I16/H16,0) | K16: =MAX(0,SUM($F$2:F16)) | L16: =IFERROR(K16/Configuracion!$K$2,0) | M16: =SUMIFS(Flujo_Caja!H:H,Flujo_Caja!B:B,B16,Flujo_Caja!C:C,C16)
D17: =SUMIFS(Ingresos!J:J,Ingresos!D:D,">="&DATE(C17,B17,1),Ingresos!D:D,"<"&EDATE(DATE(C17,B17,1),1)) | E17: =SUMIFS(Egresos!H:H,Egresos!B:B,">="&DATE(C17,B17,1),Egresos!B:B,"<"&EDATE(DATE(C17,B17,1),1))+SUMIFS(Gastos_Mensuales!H:H,Gastos_Mensuales!B:B,B17,Gastos_Mensuales!C:C,C17)+SUMIFS(Impuestos!I:I,Impuestos!B:B,B17,Impuestos!C:C,C17) | F17: =D17-E17 | G17: =IFERROR(F17/D17,0) | H17: =COUNTIFS(Cotizaciones!J:J,"Enviada",Cotizaciones!B:B,">="&DATE(C17,B17,1),Cotizaciones!B:B,"<"&EDATE(DATE(C17,B17,1),1)) | I17: =COUNTIFS(Cotizaciones!J:J,"Aprobada",Cotizaciones!B:B,">="&DATE(C17,B17,1),Cotizaciones!B:B,"<"&EDATE(DATE(C17,B17,1),1)) | J17: =IFERROR(I17/H17,0) | K17: =MAX(0,SUM($F$2:F17)) | L17: =IFERROR(K17/Configuracion!$K$2,0) | M17: =SUMIFS(Flujo_Caja!H:H,Flujo_Caja!B:B,B17,Flujo_Caja!C:C,C17)
D18: =SUMIFS(Ingresos!J:J,Ingresos!D:D,">="&DATE(C18,B18,1),Ingresos!D:D,"<"&EDATE(DATE(C18,B18,1),1)) | E18: =SUMIFS(Egresos!H:H,Egresos!B:B,">="&DATE(C18,B18,1),Egresos!B:B,"<"&EDATE(DATE(C18,B18,1),1))+SUMIFS(Gastos_Mensuales!H:H,Gastos_Mensuales!B:B,B18,Gastos_Mensuales!C:C,C18)+SUMIFS(Impuestos!I:I,Impuestos!B:B,B18,Impuestos!C:C,C18) | F18: =D18-E18 | G18: =IFERROR(F18/D18,0) | H18: =COUNTIFS(Cotizaciones!J:J,"Enviada",Cotizaciones!B:B,">="&DATE(C18,B18,1),Cotizaciones!B:B,"<"&EDATE(DATE(C18,B18,1),1)) | I18: =COUNTIFS(Cotizaciones!J:J,"Aprobada",Cotizaciones!B:B,">="&DATE(C18,B18,1),Cotizaciones!B:B,"<"&EDATE(DATE(C18,B18,1),1)) | J18: =IFERROR(I18/H18,0) | K18: =MAX(0,SUM($F$2:F18)) | L18: =IFERROR(K18/Configuracion!$K$2,0) | M18: =SUMIFS(Flujo_Caja!H:H,Flujo_Caja!B:B,B18,Flujo_Caja!C:C,C18)
D19: =SUMIFS(Ingresos!J:J,Ingresos!D:D,">="&DATE(C19,B19,1),Ingresos!D:D,"<"&EDATE(DATE(C19,B19,1),1)) | E19: =SUMIFS(Egresos!H:H,Egresos!B:B,">="&DATE(C19,B19,1),Egresos!B:B,"<"&EDATE(DATE(C19,B19,1),1))+SUMIFS(Gastos_Mensuales!H:H,Gastos_Mensuales!B:B,B19,Gastos_Mensuales!C:C,C19)+SUMIFS(Impuestos!I:I,Impuestos!B:B,B19,Impuestos!C:C,C19) | F19: =D19-E19 | G19: =IFERROR(F19/D19,0) | H19: =COUNTIFS(Cotizaciones!J:J,"Enviada",Cotizaciones!B:B,">="&DATE(C19,B19,1),Cotizaciones!B:B,"<"&EDATE(DATE(C19,B19,1),1)) | I19: =COUNTIFS(Cotizaciones!J:J,"Aprobada",Cotizaciones!B:B,">="&DATE(C19,B19,1),Cotizaciones!B:B,"<"&EDATE(DATE(C19,B19,1),1)) | J19: =IFERROR(I19/H19,0) | K19: =MAX(0,SUM($F$2:F19)) | L19: =IFERROR(K19/Configuracion!$K$2,0) | M19: =SUMIFS(Flujo_Caja!H:H,Flujo_Caja!B:B,B19,Flujo_Caja!C:C,C19)
D20: =SUMIFS(Ingresos!J:J,Ingresos!D:D,">="&DATE(C20,B20,1),Ingresos!D:D,"<"&EDATE(DATE(C20,B20,1),1)) | E20: =SUMIFS(Egresos!H:H,Egresos!B:B,">="&DATE(C20,B20,1),Egresos!B:B,"<"&EDATE(DATE(C20,B20,1),1))+SUMIFS(Gastos_Mensuales!H:H,Gastos_Mensuales!B:B,B20,Gastos_Mensuales!C:C,C20)+SUMIFS(Impuestos!I:I,Impuestos!B:B,B20,Impuestos!C:C,C20) | F20: =D20-E20 | G20: =IFERROR(F20/D20,0) | H20: =COUNTIFS(Cotizaciones!J:J,"Enviada",Cotizaciones!B:B,">="&DATE(C20,B20,1),Cotizaciones!B:B,"<"&EDATE(DATE(C20,B20,1),1)) | I20: =COUNTIFS(Cotizaciones!J:J,"Aprobada",Cotizaciones!B:B,">="&DATE(C20,B20,1),Cotizaciones!B:B,"<"&EDATE(DATE(C20,B20,1),1)) | J20: =IFERROR(I20/H20,0) | K20: =MAX(0,SUM($F$2:F20)) | L20: =IFERROR(K20/Configuracion!$K$2,0) | M20: =SUMIFS(Flujo_Caja!H:H,Flujo_Caja!B:B,B20,Flujo_Caja!C:C,C20)
D21: =SUMIFS(Ingresos!J:J,Ingresos!D:D,">="&DATE(C21,B21,1),Ingresos!D:D,"<"&EDATE(DATE(C21,B21,1),1)) | E21: =SUMIFS(Egresos!H:H,Egresos!B:B,">="&DATE(C21,B21,1),Egresos!B:B,"<"&EDATE(DATE(C21,B21,1),1))+SUMIFS(Gastos_Mensuales!H:H,Gastos_Mensuales!B:B,B21,Gastos_Mensuales!C:C,C21)+SUMIFS(Impuestos!I:I,Impuestos!B:B,B21,Impuestos!C:C,C21) | F21: =D21-E21 | G21: =IFERROR(F21/D21,0) | H21: =COUNTIFS(Cotizaciones!J:J,"Enviada",Cotizaciones!B:B,">="&DATE(C21,B21,1),Cotizaciones!B:B,"<"&EDATE(DATE(C21,B21,1),1)) | I21: =COUNTIFS(Cotizaciones!J:J,"Aprobada",Cotizaciones!B:B,">="&DATE(C21,B21,1),Cotizaciones!B:B,"<"&EDATE(DATE(C21,B21,1),1)) | J21: =IFERROR(I21/H21,0) | K21: =MAX(0,SUM($F$2:F21)) | L21: =IFERROR(K21/Configuracion!$K$2,0) | M21: =SUMIFS(Flujo_Caja!H:H,Flujo_Caja!B:B,B21,Flujo_Caja!C:C,C21)
D22: =SUMIFS(Ingresos!J:J,Ingresos!D:D,">="&DATE(C22,B22,1),Ingresos!D:D,"<"&EDATE(DATE(C22,B22,1),1)) | E22: =SUMIFS(Egresos!H:H,Egresos!B:B,">="&DATE(C22,B22,1),Egresos!B:B,"<"&EDATE(DATE(C22,B22,1),1))+SUMIFS(Gastos_Mensuales!H:H,Gastos_Mensuales!B:B,B22,Gastos_Mensuales!C:C,C22)+SUMIFS(Impuestos!I:I,Impuestos!B:B,B22,Impuestos!C:C,C22) | F22: =D22-E22 | G22: =IFERROR(F22/D22,0) | H22: =COUNTIFS(Cotizaciones!J:J,"Enviada",Cotizaciones!B:B,">="&DATE(C22,B22,1),Cotizaciones!B:B,"<"&EDATE(DATE(C22,B22,1),1)) | I22: =COUNTIFS(Cotizaciones!J:J,"Aprobada",Cotizaciones!B:B,">="&DATE(C22,B22,1),Cotizaciones!B:B,"<"&EDATE(DATE(C22,B22,1),1)) | J22: =IFERROR(I22/H22,0) | K22: =MAX(0,SUM($F$2:F22)) | L22: =IFERROR(K22/Configuracion!$K$2,0) | M22: =SUMIFS(Flujo_Caja!H:H,Flujo_Caja!B:B,B22,Flujo_Caja!C:C,C22)
D23: =SUMIFS(Ingresos!J:J,Ingresos!D:D,">="&DATE(C23,B23,1),Ingresos!D:D,"<"&EDATE(DATE(C23,B23,1),1)) | E23: =SUMIFS(Egresos!H:H,Egresos!B:B,">="&DATE(C23,B23,1),Egresos!B:B,"<"&EDATE(DATE(C23,B23,1),1))+SUMIFS(Gastos_Mensuales!H:H,Gastos_Mensuales!B:B,B23,Gastos_Mensuales!C:C,C23)+SUMIFS(Impuestos!I:I,Impuestos!B:B,B23,Impuestos!C:C,C23) | F23: =D23-E23 | G23: =IFERROR(F23/D23,0) | H23: =COUNTIFS(Cotizaciones!J:J,"Enviada",Cotizaciones!B:B,">="&DATE(C23,B23,1),Cotizaciones!B:B,"<"&EDATE(DATE(C23,B23,1),1)) | I23: =COUNTIFS(Cotizaciones!J:J,"Aprobada",Cotizaciones!B:B,">="&DATE(C23,B23,1),Cotizaciones!B:B,"<"&EDATE(DATE(C23,B23,1),1)) | J23: =IFERROR(I23/H23,0) | K23: =MAX(0,SUM($F$2:F23)) | L23: =IFERROR(K23/Configuracion!$K$2,0) | M23: =SUMIFS(Flujo_Caja!H:H,Flujo_Caja!B:B,B23,Flujo_Caja!C:C,C23)
